NAMESPACE                 LAST SEEN   TYPE      REASON                             OBJECT                                                           MESSAGE
default                   37m         Normal    Starting                           node/kubernaut-hub-control-plane                                 
default                   37m         Normal    NodeHasSufficientPID               node/kubernaut-hub-control-plane                                 Node kubernaut-hub-control-plane status is now: NodeHasSufficientPID
default                   37m         Normal    NodeHasSufficientMemory            node/kubernaut-hub-control-plane                                 Node kubernaut-hub-control-plane status is now: NodeHasSufficientMemory
default                   37m         Normal    Starting                           node/kubernaut-hub-control-plane                                 Starting kubelet.
default                   37m         Normal    NodeHasSufficientMemory            node/kubernaut-hub-control-plane                                 Node kubernaut-hub-control-plane status is now: NodeHasSufficientMemory
kube-system               37m         Normal    SuccessfulCreate                   replicaset/coredns-559f6c778d                                    Created pod: coredns-559f6c778d-m82c4
kube-system               37m         Normal    SuccessfulCreate                   replicaset/coredns-559f6c778d                                    Created pod: coredns-559f6c778d-z7w74
default                   37m         Normal    NodeHasNoDiskPressure              node/kubernaut-hub-control-plane                                 Node kubernaut-hub-control-plane status is now: NodeHasNoDiskPressure
kube-system               37m         Normal    ScalingReplicaSet                  deployment/coredns                                               Scaled up replica set coredns-559f6c778d from 0 to 2
kube-system               37m         Normal    LeaderElection                     lease/kube-controller-manager                                    kubernaut-hub-control-plane_cf143c27-1684-4970-baa2-c6ea781718ba became leader
default                   37m         Normal    NodeHasSufficientPID               node/kubernaut-hub-control-plane                                 Node kubernaut-hub-control-plane status is now: NodeHasSufficientPID
default                   37m         Normal    RegisteredNode                     node/kubernaut-hub-control-plane                                 Node kubernaut-hub-control-plane event: Registered Node kubernaut-hub-control-plane in Controller
kube-system               37m         Normal    SuccessfulCreate                   daemonset/kube-proxy                                             Created pod: kube-proxy-9chfw
default                   37m         Normal    NodeHasNoDiskPressure              node/kubernaut-hub-control-plane                                 Node kubernaut-hub-control-plane status is now: NodeHasNoDiskPressure
kube-system               37m         Warning   FailedScheduling                   pod/coredns-559f6c778d-z7w74                                     0/1 nodes are available: 1 node(s) had untolerated taint(s). preemption: 0/1 nodes are available: 1 Preemption is not helpful for scheduling.
kube-system               37m         Normal    Scheduled                          pod/kube-proxy-9chfw                                             Successfully assigned kube-system/kube-proxy-9chfw to kubernaut-hub-control-plane
kube-system               37m         Normal    LeaderElection                     lease/kube-scheduler                                             kubernaut-hub-control-plane_a58a565c-5bd7-41d3-9020-e4afc6002818 became leader
kube-system               37m         Warning   FailedScheduling                   pod/coredns-559f6c778d-m82c4                                     0/1 nodes are available: 1 node(s) had untolerated taint(s). preemption: 0/1 nodes are available: 1 Preemption is not helpful for scheduling.
kube-system               37m         Normal    Pulled                             pod/kube-proxy-9chfw                                             Container image "registry.k8s.io/kube-proxy:v1.37.0" already present on machine and can be accessed by the pod
kube-system               37m         Normal    Created                            pod/kube-proxy-9chfw                                             Container created
kube-system               37m         Normal    Scheduled                          pod/kindnet-5mf85                                                Successfully assigned kube-system/kindnet-5mf85 to kubernaut-hub-control-plane
local-path-storage        37m         Normal    ScalingReplicaSet                  deployment/local-path-provisioner                                Scaled up replica set local-path-provisioner-75f7fc7dc5 from 0 to 1
local-path-storage        37m         Warning   FailedScheduling                   pod/local-path-provisioner-75f7fc7dc5-q66cf                      0/1 nodes are available: 1 node(s) had untolerated taint(s). preemption: 0/1 nodes are available: 1 Preemption is not helpful for scheduling.
local-path-storage        37m         Normal    SuccessfulCreate                   replicaset/local-path-provisioner-75f7fc7dc5                     Created pod: local-path-provisioner-75f7fc7dc5-q66cf
kube-system               37m         Normal    SuccessfulCreate                   daemonset/kindnet                                                Created pod: kindnet-5mf85
kube-system               37m         Normal    Started                            pod/kube-proxy-9chfw                                             Container started
kube-system               37m         Normal    Pulled                             pod/kindnet-5mf85                                                Container image "docker.io/kindest/kindnetd:v20260820-69b56db7" already present on machine and can be accessed by the pod
kube-system               37m         Normal    Started                            pod/kindnet-5mf85                                                Container started
kube-system               37m         Normal    Created                            pod/kindnet-5mf85                                                Container created
cert-manager              37m         Normal    SuccessfulCreate                   replicaset/cert-manager-cainjector-79dfb8cb5f                    Created pod: cert-manager-cainjector-79dfb8cb5f-pvmw7
cert-manager              37m         Normal    ScalingReplicaSet                  deployment/cert-manager                                          Scaled up replica set cert-manager-7c94d65774 from 0 to 1
cert-manager              37m         Warning   FailedScheduling                   pod/cert-manager-cainjector-79dfb8cb5f-pvmw7                     0/1 nodes are available: 1 node(s) had untolerated taint(s). preemption: 0/1 nodes are available: 1 Preemption is not helpful for scheduling.
cert-manager              37m         Warning   FailedScheduling                   pod/cert-manager-7c94d65774-jj2tp                                0/1 nodes are available: 1 node(s) had untolerated taint(s). preemption: 0/1 nodes are available: 1 Preemption is not helpful for scheduling.
cert-manager              37m         Normal    ScalingReplicaSet                  deployment/cert-manager-cainjector                               Scaled up replica set cert-manager-cainjector-79dfb8cb5f from 0 to 1
cert-manager              37m         Normal    SuccessfulCreate                   replicaset/cert-manager-webhook-6589c57d88                       Created pod: cert-manager-webhook-6589c57d88-rlq8c
cert-manager              37m         Normal    SuccessfulCreate                   replicaset/cert-manager-7c94d65774                               Created pod: cert-manager-7c94d65774-jj2tp
cert-manager              37m         Warning   FailedScheduling                   pod/cert-manager-webhook-6589c57d88-rlq8c                        0/1 nodes are available: 1 node(s) had untolerated taint(s). preemption: 0/1 nodes are available: 1 Preemption is not helpful for scheduling.
cert-manager              37m         Normal    ScalingReplicaSet                  deployment/cert-manager-webhook                                  Scaled up replica set cert-manager-webhook-6589c57d88 from 0 to 1
default                   37m         Normal    NodeReady                          node/kubernaut-hub-control-plane                                 Node kubernaut-hub-control-plane status is now: NodeReady
kube-system               37m         Normal    Pulled                             pod/coredns-559f6c778d-m82c4                                     Container image "registry.k8s.io/coredns/coredns:v1.14.6" already present on machine and can be accessed by the pod
local-path-storage        37m         Normal    Scheduled                          pod/local-path-provisioner-75f7fc7dc5-q66cf                      Successfully assigned local-path-storage/local-path-provisioner-75f7fc7dc5-q66cf to kubernaut-hub-control-plane
local-path-storage        37m         Normal    Pulled                             pod/local-path-provisioner-75f7fc7dc5-q66cf                      Container image "docker.io/kindest/local-path-provisioner:v20260820-69b56db7" already present on machine and can be accessed by the pod
cert-manager              37m         Normal    Pulling                            pod/cert-manager-7c94d65774-jj2tp                                Pulling image "quay.io/jetstack/cert-manager-controller:v1.20.3"
cert-manager              37m         Normal    Scheduled                          pod/cert-manager-7c94d65774-jj2tp                                Successfully assigned cert-manager/cert-manager-7c94d65774-jj2tp to kubernaut-hub-control-plane
cert-manager              37m         Normal    Pulling                            pod/cert-manager-webhook-6589c57d88-rlq8c                        Pulling image "quay.io/jetstack/cert-manager-webhook:v1.20.3"
cert-manager              37m         Normal    Scheduled                          pod/cert-manager-cainjector-79dfb8cb5f-pvmw7                     Successfully assigned cert-manager/cert-manager-cainjector-79dfb8cb5f-pvmw7 to kubernaut-hub-control-plane
kube-system               37m         Normal    Pulled                             pod/coredns-559f6c778d-z7w74                                     Container image "registry.k8s.io/coredns/coredns:v1.14.6" already present on machine and can be accessed by the pod
cert-manager              37m         Normal    Pulling                            pod/cert-manager-cainjector-79dfb8cb5f-pvmw7                     Pulling image "quay.io/jetstack/cert-manager-cainjector:v1.20.3"
cert-manager              37m         Normal    Scheduled                          pod/cert-manager-webhook-6589c57d88-rlq8c                        Successfully assigned cert-manager/cert-manager-webhook-6589c57d88-rlq8c to kubernaut-hub-control-plane
kube-system               37m         Normal    Scheduled                          pod/coredns-559f6c778d-m82c4                                     Successfully assigned kube-system/coredns-559f6c778d-m82c4 to kubernaut-hub-control-plane
kube-system               37m         Normal    Scheduled                          pod/coredns-559f6c778d-z7w74                                     Successfully assigned kube-system/coredns-559f6c778d-z7w74 to kubernaut-hub-control-plane
local-path-storage        37m         Normal    TaintManagerEviction               pod/local-path-provisioner-75f7fc7dc5-q66cf                      Cancelling deletion of Pod local-path-storage/local-path-provisioner-75f7fc7dc5-q66cf
kube-system               37m         Warning   Unhealthy                          pod/coredns-559f6c778d-z7w74                                     Readiness probe failed: Get "http://10.244.0.5:8181/ready": dial tcp 10.244.0.5:8181: connect: connection refused
kube-system               37m         Warning   Unhealthy                          pod/coredns-559f6c778d-m82c4                                     Readiness probe failed: Get "http://10.244.0.7:8181/ready": dial tcp 10.244.0.7:8181: connect: connection refused
kube-system               37m         Normal    Created                            pod/coredns-559f6c778d-m82c4                                     Container created
local-path-storage        37m         Normal    Started                            pod/local-path-provisioner-75f7fc7dc5-q66cf                      Container started
cert-manager              37m         Normal    TaintManagerEviction               pod/cert-manager-webhook-6589c57d88-rlq8c                        Cancelling deletion of Pod cert-manager/cert-manager-webhook-6589c57d88-rlq8c
kube-system               37m         Normal    Created                            pod/coredns-559f6c778d-z7w74                                     Container created
cert-manager              37m         Normal    TaintManagerEviction               pod/cert-manager-7c94d65774-jj2tp                                Cancelling deletion of Pod cert-manager/cert-manager-7c94d65774-jj2tp
kube-system               37m         Normal    TaintManagerEviction               pod/coredns-559f6c778d-m82c4                                     Cancelling deletion of Pod kube-system/coredns-559f6c778d-m82c4
cert-manager              37m         Normal    TaintManagerEviction               pod/cert-manager-cainjector-79dfb8cb5f-pvmw7                     Cancelling deletion of Pod cert-manager/cert-manager-cainjector-79dfb8cb5f-pvmw7
kube-system               37m         Normal    Started                            pod/coredns-559f6c778d-m82c4                                     Container started
local-path-storage        37m         Normal    Created                            pod/local-path-provisioner-75f7fc7dc5-q66cf                      Container created
kube-system               37m         Normal    Started                            pod/coredns-559f6c778d-z7w74                                     Container started
kube-system               37m         Normal    TaintManagerEviction               pod/coredns-559f6c778d-z7w74                                     Cancelling deletion of Pod kube-system/coredns-559f6c778d-z7w74
cert-manager              37m         Normal    Pulled                             pod/cert-manager-webhook-6589c57d88-rlq8c                        Successfully pulled image "quay.io/jetstack/cert-manager-webhook:v1.20.3" in 5.592s (5.592s including waiting). Image size: 17459880 bytes.
cert-manager              37m         Normal    Started                            pod/cert-manager-webhook-6589c57d88-rlq8c                        Container started
cert-manager              37m         Normal    Created                            pod/cert-manager-webhook-6589c57d88-rlq8c                        Container created
cert-manager              37m         Normal    Pulled                             pod/cert-manager-cainjector-79dfb8cb5f-pvmw7                     Successfully pulled image "quay.io/jetstack/cert-manager-cainjector:v1.20.3" in 4.433s (10.009s including waiting). Image size: 14651291 bytes.
kube-system               37m         Normal    LeaderElection                     lease/cert-manager-cainjector-leader-election                    cert-manager-cainjector-79dfb8cb5f-pvmw7_8ed7fa53-f83c-4b48-9033-da55404e911b became leader
default                   37m         Normal    ScalingReplicaSet                  deployment/reloader-reloader                                     Scaled up replica set reloader-reloader-b657754db from 0 to 1
default                   37m         Normal    SuccessfulCreate                   replicaset/reloader-reloader-b657754db                           Created pod: reloader-reloader-b657754db-jdl6x
cert-manager              37m         Normal    Pulled                             pod/cert-manager-7c94d65774-jj2tp                                Successfully pulled image "quay.io/jetstack/cert-manager-controller:v1.20.3" in 5.278s (15.279s including waiting). Image size: 21188877 bytes.
default                   37m         Normal    Scheduled                          pod/reloader-reloader-b657754db-jdl6x                            Successfully assigned default/reloader-reloader-b657754db-jdl6x to kubernaut-hub-control-plane
kube-system               37m         Normal    LeaderElection                     lease/cert-manager-controller                                    cert-manager-7c94d65774-jj2tp-external-cert-manager-controller became leader
default                   37m         Normal    Pulling                            pod/reloader-reloader-b657754db-jdl6x                            Pulling image "ghcr.io/stakater/reloader:v1.4.21"
default                   37m         Normal    Started                            pod/reloader-reloader-b657754db-jdl6x                            Container started
default                   37m         Normal    Created                            pod/reloader-reloader-b657754db-jdl6x                            Container created
default                   37m         Normal    Pulled                             pod/reloader-reloader-b657754db-jdl6x                            Successfully pulled image "ghcr.io/stakater/reloader:v1.4.21" in 2.222s (2.222s including waiting). Image size: 13981851 bytes.
kubernaut-system          37m         Normal    WaitingForApproval                 certificaterequest/console-tls-1                                 Not signing CertificateRequest until it is Approved
kubernaut-system          37m         Normal    WaitingForApproval                 certificaterequest/console-tls-1                                 Not signing CertificateRequest until it is Approved
idp                       37m         Normal    cert-manager.io                    certificaterequest/keycloak-tls-1                                Certificate request has been approved by cert-manager.io
idp                       37m         Normal    CertificateIssued                  certificaterequest/keycloak-tls-1                                Certificate fetched from issuer successfully
kubernaut-system          37m         Normal    KeyPairVerified                    issuer/demo-console-ca                                           Signing CA verified
kubernaut-system          37m         Normal    Requested                          certificate/console-tls                                          Created new CertificateRequest resource "console-tls-1"
kubernaut-system          37m         Normal    Generated                          certificate/console-tls                                          Stored new private key in temporary Secret resource "console-tls-m6qpr"
kubernaut-system          37m         Normal    Issuing                            certificate/console-tls                                          Issuing certificate as Secret does not exist
kubernaut-system          37m         Normal    CertificateIssued                  certificaterequest/console-tls-1                                 Certificate fetched from issuer successfully
kubernaut-system          37m         Normal    cert-manager.io                    certificaterequest/console-tls-1                                 Certificate request has been approved by cert-manager.io
kubernaut-system          37m         Normal    WaitingForApproval                 certificaterequest/console-tls-1                                 Not signing CertificateRequest until it is Approved
kubernaut-system          37m         Normal    WaitingForApproval                 certificaterequest/console-tls-1                                 Not signing CertificateRequest until it is Approved
kubernaut-system          37m         Normal    WaitingForApproval                 certificaterequest/console-tls-1                                 Not signing CertificateRequest until it is Approved
idp                       37m         Normal    KeyPairVerified                    issuer/inter-service-ca-issuer                                   Signing CA verified
idp                       37m         Normal    WaitingForApproval                 certificaterequest/keycloak-tls-1                                Not signing CertificateRequest until it is Approved
idp                       37m         Normal    WaitingForApproval                 certificaterequest/keycloak-tls-1                                Not signing CertificateRequest until it is Approved
idp                       37m         Normal    WaitingForApproval                 certificaterequest/keycloak-tls-1                                Not signing CertificateRequest until it is Approved
idp                       37m         Normal    WaitingForApproval                 certificaterequest/keycloak-tls-1                                Not signing CertificateRequest until it is Approved
idp                       37m         Normal    Generated                          certificate/keycloak-tls                                         Stored new private key in temporary Secret resource "keycloak-tls-fdbrf"
idp                       37m         Normal    WaitingForApproval                 certificaterequest/keycloak-tls-1                                Not signing CertificateRequest until it is Approved
idp                       37m         Normal    Requested                          certificate/keycloak-tls                                         Created new CertificateRequest resource "keycloak-tls-1"
idp                       37m         Normal    Issuing                            certificate/keycloak-tls                                         The certificate has been successfully issued
idp                       37m         Normal    Issuing                            certificate/keycloak-tls                                         Issuing certificate as Secret does not exist
idp                       37m         Normal    Provisioning                       persistentvolumeclaim/keycloak-data                              External provisioner is provisioning volume for claim "idp/keycloak-data"
idp                       37m         Normal    ScalingReplicaSet                  deployment/keycloak                                              Scaled up replica set keycloak-5c8c764ddc from 0 to 1
kubernaut-system          37m         Normal    Issuing                            certificate/console-tls                                          The certificate has been successfully issued
idp                       37m         Normal    SuccessfulCreate                   replicaset/keycloak-5c8c764ddc                                   Created pod: keycloak-5c8c764ddc-lmn4h
idp                       37m         Normal    WaitForFirstConsumer               persistentvolumeclaim/keycloak-data                              waiting for first consumer to be created before binding
idp                       37m         Normal    ExternalProvisioning               persistentvolumeclaim/keycloak-data                              Waiting for a volume to be created either by the external provisioner 'rancher.io/local-path' or manually by the system administrator. If volume creation is delayed, please verify that the provisioner is running and correctly registered.
local-path-storage        37m         Normal    Started                            pod/helper-pod-create-pvc-54e1783a-053f-412b-ab47-1079336bf925   Container started
local-path-storage        37m         Normal    Created                            pod/helper-pod-create-pvc-54e1783a-053f-412b-ab47-1079336bf925   Container created
local-path-storage        37m         Normal    Pulled                             pod/helper-pod-create-pvc-54e1783a-053f-412b-ab47-1079336bf925   Container image "docker.io/kindest/local-path-helper:v20260131-7181c60a" already present on machine and can be accessed by the pod
idp                       37m         Normal    ProvisioningSucceeded              persistentvolumeclaim/keycloak-data                              Successfully provisioned volume pvc-54e1783a-053f-412b-ab47-1079336bf925
idp                       37m         Normal    Scheduled                          pod/keycloak-5c8c764ddc-lmn4h                                    Successfully assigned idp/keycloak-5c8c764ddc-lmn4h to kubernaut-hub-control-plane
idp                       37m         Normal    Pulling                            pod/keycloak-5c8c764ddc-lmn4h                                    Pulling image "quay.io/keycloak/keycloak:26.6.4"
idp                       36m         Normal    Pulled                             pod/keycloak-5c8c764ddc-lmn4h                                    Successfully pulled image "quay.io/keycloak/keycloak:26.6.4" in 13.488s (13.488s including waiting). Image size: 264077219 bytes.
idp                       36m         Normal    Created                            pod/keycloak-5c8c764ddc-lmn4h                                    Container created
idp                       36m         Normal    Started                            pod/keycloak-5c8c764ddc-lmn4h                                    Container started
idp                       36m         Warning   Unhealthy                          pod/keycloak-5c8c764ddc-lmn4h                                    Liveness probe failed: Get "https://10.244.0.10:8443/realms/master": dial tcp 10.244.0.10:8443: connect: connection refused
idp                       36m         Warning   Unhealthy                          pod/keycloak-5c8c764ddc-lmn4h                                    Readiness probe failed: Get "https://10.244.0.10:8443/realms/master": dial tcp 10.244.0.10:8443: connect: connection refused
traefik-system            36m         Normal    Scheduled                          pod/traefik-5896f688b7-6q9tx                                     Successfully assigned traefik-system/traefik-5896f688b7-6q9tx to kubernaut-hub-control-plane
traefik-system            36m         Normal    ScalingReplicaSet                  deployment/traefik                                               Scaled up replica set traefik-5896f688b7 from 0 to 1
traefik-system            36m         Normal    SuccessfulCreate                   replicaset/traefik-5896f688b7                                    Created pod: traefik-5896f688b7-6q9tx
traefik-system            36m         Normal    Pulling                            pod/traefik-5896f688b7-6q9tx                                     Pulling image "docker.io/traefik:v3.7.13"
traefik-system            36m         Normal    Pulled                             pod/traefik-5896f688b7-6q9tx                                     Successfully pulled image "docker.io/traefik:v3.7.13" in 5.381s (5.381s including waiting). Image size: 50026539 bytes.
traefik-system            36m         Normal    Started                            pod/traefik-5896f688b7-6q9tx                                     Container started
traefik-system            36m         Normal    Created                            pod/traefik-5896f688b7-6q9tx                                     Container created
kube-system               35m         Normal    Killing                            pod/kube-apiserver-kubernaut-hub-control-plane                   Stopping container kube-apiserver
kube-system               35m         Warning   Unhealthy                          pod/kube-apiserver-kubernaut-hub-control-plane                   Readiness probe failed: Get "https://10.89.0.4:6443/readyz": dial tcp 10.89.0.4:6443: connect: connection refused
kube-system               35m         Normal    Started                            pod/kube-scheduler-kubernaut-hub-control-plane                   Container started
kube-system               35m         Normal    Pulled                             pod/kube-controller-manager-kubernaut-hub-control-plane          Container image "registry.k8s.io/kube-controller-manager:v1.37.0" already present on machine and can be accessed by the pod
kube-system               35m         Normal    Created                            pod/kube-controller-manager-kubernaut-hub-control-plane          Container created
kube-system               35m         Normal    Pulled                             pod/kube-scheduler-kubernaut-hub-control-plane                   Container image "registry.k8s.io/kube-scheduler:v1.37.0" already present on machine and can be accessed by the pod
kube-system               35m         Normal    Started                            pod/kube-controller-manager-kubernaut-hub-control-plane          Container started
kube-system               35m         Normal    Created                            pod/kube-scheduler-kubernaut-hub-control-plane                   Container created
kube-system               35m         Normal    Started                            pod/kube-apiserver-kubernaut-hub-control-plane                   Container started
kube-system               35m         Normal    Created                            pod/kube-apiserver-kubernaut-hub-control-plane                   Container created
kube-system               35m         Normal    Pulled                             pod/kube-apiserver-kubernaut-hub-control-plane                   Container image "registry.k8s.io/kube-apiserver:v1.37.0" already present on machine and can be accessed by the pod
kube-system               35m         Normal    Killing                            pod/kube-apiserver-kubernaut-hub-control-plane                   Stopping container kube-apiserver
kube-system               35m         Warning   Unhealthy                          pod/kube-scheduler-kubernaut-hub-control-plane                   Readiness probe failed: HTTP probe failed with statuscode: 500
cert-manager              34m         Normal    Started                            pod/cert-manager-7c94d65774-jj2tp                                Container started
cert-manager              34m         Normal    Created                            pod/cert-manager-7c94d65774-jj2tp                                Container created
cert-manager              34m         Normal    Pulled                             pod/cert-manager-7c94d65774-jj2tp                                Container image "quay.io/jetstack/cert-manager-controller:v1.20.3" already present on machine and can be accessed by the pod
kube-system               34m         Normal    Created                            pod/kube-apiserver-kubernaut-hub-control-plane                   Container created
kube-system               34m         Normal    Pulled                             pod/kube-apiserver-kubernaut-hub-control-plane                   Container image "registry.k8s.io/kube-apiserver:v1.37.0" already present on machine and can be accessed by the pod
kube-system               34m         Normal    Started                            pod/kube-apiserver-kubernaut-hub-control-plane                   Container started
default                   34m         Normal    RegisteredNode                     node/kubernaut-hub-control-plane                                 Node kubernaut-hub-control-plane event: Registered Node kubernaut-hub-control-plane in Controller
kube-system               34m         Normal    LeaderElection                     lease/kube-controller-manager                                    kubernaut-hub-control-plane_06a3eb4a-39fb-494c-8f4f-8f12fab1c16b became leader
cert-manager              34m         Warning   BackOff                            pod/cert-manager-cainjector-79dfb8cb5f-pvmw7                     Back-off restarting failed container cert-manager-cainjector in pod cert-manager-cainjector-79dfb8cb5f-pvmw7_cert-manager(858b7b7f-f275-4214-8c6e-69467aa32632)
kubernaut-system          34m         Normal    KeyPairVerified                    issuer/demo-console-ca                                           Signing CA verified
kube-system               34m         Normal    LeaderElection                     lease/cert-manager-controller                                    cert-manager-7c94d65774-jj2tp-external-cert-manager-controller became leader
idp                       34m         Normal    KeyPairVerified                    issuer/inter-service-ca-issuer                                   Signing CA verified
kube-system               33m         Normal    LeaderElection                     lease/kube-scheduler                                             kubernaut-hub-control-plane_29be442a-02e5-402a-a598-c2be24e7a104 became leader
cert-manager              33m         Normal    Started                            pod/cert-manager-cainjector-79dfb8cb5f-pvmw7                     Container started
cert-manager              33m         Normal    Created                            pod/cert-manager-cainjector-79dfb8cb5f-pvmw7                     Container created
cert-manager              33m         Normal    Pulled                             pod/cert-manager-cainjector-79dfb8cb5f-pvmw7                     Container image "quay.io/jetstack/cert-manager-cainjector:v1.20.3" already present on machine and can be accessed by the pod
kube-system               32m         Normal    LeaderElection                     lease/cert-manager-cainjector-leader-election                    cert-manager-cainjector-79dfb8cb5f-pvmw7_fa04dbed-c3d3-4e1c-9f6e-c3bea01013af became leader
envoy-gateway-system      31m         Normal    Scheduled                          pod/eg-gateway-helm-certgen-g4vvh                                Successfully assigned envoy-gateway-system/eg-gateway-helm-certgen-g4vvh to kubernaut-hub-control-plane
envoy-gateway-system      31m         Normal    SuccessfulCreate                   job/eg-gateway-helm-certgen                                      Created pod: eg-gateway-helm-certgen-g4vvh
envoy-gateway-system      31m         Normal    Pulling                            pod/eg-gateway-helm-certgen-g4vvh                                Pulling image "docker.io/envoyproxy/gateway:v1.8.1"
envoy-gateway-system      31m         Normal    Started                            pod/eg-gateway-helm-certgen-g4vvh                                Container started
envoy-gateway-system      31m         Normal    Created                            pod/eg-gateway-helm-certgen-g4vvh                                Container created
envoy-gateway-system      31m         Normal    Pulled                             pod/eg-gateway-helm-certgen-g4vvh                                Successfully pulled image "docker.io/envoyproxy/gateway:v1.8.1" in 6.533s (6.533s including waiting). Image size: 68130293 bytes.
envoy-gateway-system      31m         Normal    Scheduled                          pod/envoy-gateway-57c8f59448-x2478                               Successfully assigned envoy-gateway-system/envoy-gateway-57c8f59448-x2478 to kubernaut-hub-control-plane
envoy-gateway-system      31m         Normal    Completed                          job/eg-gateway-helm-certgen                                      Job completed
envoy-gateway-system      31m         Normal    Pulled                             pod/envoy-gateway-57c8f59448-x2478                               Container image "docker.io/envoyproxy/gateway:v1.8.1" already present on machine and can be accessed by the pod
envoy-gateway-system      31m         Normal    Created                            pod/envoy-gateway-57c8f59448-x2478                               Container created
envoy-gateway-system      31m         Normal    Started                            pod/envoy-gateway-57c8f59448-x2478                               Container started
envoy-gateway-system      31m         Normal    SuccessfulCreate                   replicaset/envoy-gateway-57c8f59448                              Created pod: envoy-gateway-57c8f59448-x2478
envoy-gateway-system      31m         Normal    ScalingReplicaSet                  deployment/envoy-gateway                                         Scaled up replica set envoy-gateway-57c8f59448 from 0 to 1
envoy-gateway-system      31m         Normal    LeaderElection                     lease/5b9825d2.gateway.envoyproxy.io                             envoy-gateway-57c8f59448-x2478_5ca8a6af-3c5c-459a-a567-809f63178049 became leader
envoy-ai-gateway-system   31m         Normal    ScalingReplicaSet                  deployment/ai-gateway-controller                                 Scaled up replica set ai-gateway-controller-765b9d6bc5 from 0 to 1
envoy-ai-gateway-system   31m         Normal    SuccessfulCreate                   replicaset/ai-gateway-controller-765b9d6bc5                      Created pod: ai-gateway-controller-765b9d6bc5-668z9
envoy-ai-gateway-system   31m         Normal    Pulling                            pod/ai-gateway-controller-765b9d6bc5-668z9                       Pulling image "docker.io/envoyproxy/ai-gateway-controller:v1.0.0"
envoy-ai-gateway-system   31m         Normal    Scheduled                          pod/ai-gateway-controller-765b9d6bc5-668z9                       Successfully assigned envoy-ai-gateway-system/ai-gateway-controller-765b9d6bc5-668z9 to kubernaut-hub-control-plane
envoy-ai-gateway-system   30m         Normal    Pulled                             pod/ai-gateway-controller-765b9d6bc5-668z9                       Successfully pulled image "docker.io/envoyproxy/ai-gateway-controller:v1.0.0" in 4.317s (4.317s including waiting). Image size: 40277938 bytes.
envoy-ai-gateway-system   30m         Normal    Started                            pod/ai-gateway-controller-765b9d6bc5-668z9                       Container started
envoy-ai-gateway-system   30m         Normal    Created                            pod/ai-gateway-controller-765b9d6bc5-668z9                       Container created
envoy-ai-gateway-system   30m         Normal    LeaderElection                     lease/envoy-ai-gateway-controller                                ai-gateway-controller-765b9d6bc5-668z9_9d44101b-9cbd-4527-a31b-a065312c6a13 became leader
envoy-gateway-system      30m         Normal    SuccessfulCreate                   replicaset/envoy-gateway-7db45498c4                              Created pod: envoy-gateway-7db45498c4-mdn77
envoy-gateway-system      30m         Normal    ScalingReplicaSet                  deployment/envoy-gateway                                         Scaled up replica set envoy-gateway-7db45498c4 from 0 to 1
envoy-gateway-system      30m         Normal    Scheduled                          pod/envoy-gateway-7db45498c4-mdn77                               Successfully assigned envoy-gateway-system/envoy-gateway-7db45498c4-mdn77 to kubernaut-hub-control-plane
envoy-gateway-system      30m         Normal    Started                            pod/envoy-gateway-7db45498c4-mdn77                               Container started
envoy-gateway-system      30m         Normal    Pulled                             pod/envoy-gateway-7db45498c4-mdn77                               Container image "docker.io/envoyproxy/gateway:v1.8.1" already present on machine and can be accessed by the pod
envoy-gateway-system      30m         Normal    Created                            pod/envoy-gateway-7db45498c4-mdn77                               Container created
envoy-gateway-system      30m         Normal    Killing                            pod/envoy-gateway-57c8f59448-x2478                               Stopping container envoy-gateway
envoy-gateway-system      30m         Normal    SuccessfulDelete                   replicaset/envoy-gateway-57c8f59448                              Deleted pod: envoy-gateway-57c8f59448-x2478
envoy-gateway-system      30m         Normal    ScalingReplicaSet                  deployment/envoy-gateway                                         Scaled down replica set envoy-gateway-57c8f59448 from 1 to 0
envoy-gateway-system      30m         Normal    LeaderElection                     lease/5b9825d2.gateway.envoyproxy.io                             envoy-gateway-7db45498c4-mdn77_ce64ac50-1667-429b-88ef-734b66b3121b became leader
mcp-system                30m         Normal    SuccessfulCreate                   replicaset/kube-mcp-server-96bc74bd4                             Created pod: kube-mcp-server-96bc74bd4-wp92q
envoy-gateway-system      30m         Normal    Scheduled                          pod/envoy-mcp-system-mcp-gateway-7ead7c3d-8545c8b4d7-k2zft       Successfully assigned envoy-gateway-system/envoy-mcp-system-mcp-gateway-7ead7c3d-8545c8b4d7-k2zft to kubernaut-hub-control-plane
envoy-gateway-system      30m         Normal    Pulling                            pod/envoy-mcp-system-mcp-gateway-7ead7c3d-8545c8b4d7-k2zft       Pulling image "docker.io/envoyproxy/envoy:distroless-v1.38.1"
mcp-system                30m         Normal    ScalingReplicaSet                  deployment/kube-mcp-server                                       Scaled up replica set kube-mcp-server-96bc74bd4 from 0 to 1
mcp-system                30m         Normal    Pulling                            pod/kube-mcp-server-96bc74bd4-wp92q                              Pulling image "ghcr.io/containers/kubernetes-mcp-server@sha256:4219880ffae9b61f5cf8e27c0536d4001336016a6af77dc5a63dfaf9ce938b97"
mcp-system                30m         Normal    Scheduled                          pod/kube-mcp-server-96bc74bd4-wp92q                              Successfully assigned mcp-system/kube-mcp-server-96bc74bd4-wp92q to kubernaut-hub-control-plane
envoy-gateway-system      30m         Normal    ScalingReplicaSet                  deployment/envoy-mcp-system-mcp-gateway-7ead7c3d                 Scaled up replica set envoy-mcp-system-mcp-gateway-7ead7c3d-8545c8b4d7 from 0 to 1
envoy-gateway-system      30m         Normal    SuccessfulCreate                   replicaset/envoy-mcp-system-mcp-gateway-7ead7c3d-8545c8b4d7      Created pod: envoy-mcp-system-mcp-gateway-7ead7c3d-8545c8b4d7-k2zft
envoy-gateway-system      30m         Normal    Pulled                             pod/envoy-mcp-system-mcp-gateway-7ead7c3d-8545c8b4d7-k2zft       Successfully pulled image "docker.io/envoyproxy/envoy:distroless-v1.38.1" in 4.452s (4.452s including waiting). Image size: 40600322 bytes.
envoy-gateway-system      30m         Normal    Created                            pod/envoy-mcp-system-mcp-gateway-7ead7c3d-8545c8b4d7-k2zft       Container created
envoy-gateway-system      30m         Normal    Started                            pod/envoy-mcp-system-mcp-gateway-7ead7c3d-8545c8b4d7-k2zft       Container started
envoy-gateway-system      30m         Normal    Pulling                            pod/envoy-mcp-system-mcp-gateway-7ead7c3d-8545c8b4d7-k2zft       Pulling image "docker.io/envoyproxy/gateway-dev:latest"
mcp-system                30m         Normal    Created                            pod/kube-mcp-server-96bc74bd4-wp92q                              Container created
mcp-system                30m         Normal    Started                            pod/kube-mcp-server-96bc74bd4-wp92q                              Container started
mcp-system                30m         Normal    Pulled                             pod/kube-mcp-server-96bc74bd4-wp92q                              Successfully pulled image "ghcr.io/containers/kubernetes-mcp-server@sha256:4219880ffae9b61f5cf8e27c0536d4001336016a6af77dc5a63dfaf9ce938b97" in 5.465s (9.592s including waiting). Image size: 60798794 bytes.
envoy-gateway-system      30m         Normal    Scheduled                          pod/envoy-mcp-system-mcp-gateway-7ead7c3d-5fb5c8bd9b-8dm77       Successfully assigned envoy-gateway-system/envoy-mcp-system-mcp-gateway-7ead7c3d-5fb5c8bd9b-8dm77 to kubernaut-hub-control-plane
envoy-gateway-system      30m         Normal    SuccessfulCreate                   replicaset/envoy-mcp-system-mcp-gateway-7ead7c3d-5fb5c8bd9b      Created pod: envoy-mcp-system-mcp-gateway-7ead7c3d-5fb5c8bd9b-8dm77
envoy-gateway-system      30m         Normal    Pulling                            pod/envoy-mcp-system-mcp-gateway-7ead7c3d-5fb5c8bd9b-8dm77       Pulling image "docker.io/envoyproxy/ai-gateway-extproc:v1.0.0"
envoy-gateway-system      30m         Normal    ScalingReplicaSet                  deployment/envoy-mcp-system-mcp-gateway-7ead7c3d                 Scaled up replica set envoy-mcp-system-mcp-gateway-7ead7c3d-5fb5c8bd9b from 0 to 1
envoy-gateway-system      30m         Normal    Pulled                             pod/envoy-mcp-system-mcp-gateway-7ead7c3d-8545c8b4d7-k2zft       Successfully pulled image "docker.io/envoyproxy/gateway-dev:latest" in 10.077s (15.448s including waiting). Image size: 70928918 bytes.
envoy-gateway-system      30m         Normal    Created                            pod/envoy-mcp-system-mcp-gateway-7ead7c3d-8545c8b4d7-k2zft       Container created
envoy-gateway-system      30m         Normal    Started                            pod/envoy-mcp-system-mcp-gateway-7ead7c3d-8545c8b4d7-k2zft       Container started
envoy-gateway-system      29m         Normal    Created                            pod/envoy-mcp-system-mcp-gateway-7ead7c3d-5fb5c8bd9b-8dm77       Container created
envoy-gateway-system      29m         Normal    Created                            pod/envoy-mcp-system-mcp-gateway-7ead7c3d-5fb5c8bd9b-8dm77       Container created
envoy-gateway-system      29m         Normal    Pulled                             pod/envoy-mcp-system-mcp-gateway-7ead7c3d-5fb5c8bd9b-8dm77       Container image "docker.io/envoyproxy/envoy:distroless-v1.38.1" already present on machine and can be accessed by the pod
envoy-gateway-system      29m         Normal    Started                            pod/envoy-mcp-system-mcp-gateway-7ead7c3d-5fb5c8bd9b-8dm77       Container started
envoy-gateway-system      29m         Normal    Pulled                             pod/envoy-mcp-system-mcp-gateway-7ead7c3d-5fb5c8bd9b-8dm77       Successfully pulled image "docker.io/envoyproxy/ai-gateway-extproc:v1.0.0" in 5.244s (6.88s including waiting). Image size: 31545269 bytes.
envoy-gateway-system      29m         Normal    Started                            pod/envoy-mcp-system-mcp-gateway-7ead7c3d-5fb5c8bd9b-8dm77       Container started
envoy-gateway-system      29m         Normal    Pulled                             pod/envoy-mcp-system-mcp-gateway-7ead7c3d-5fb5c8bd9b-8dm77       Container image "docker.io/envoyproxy/gateway-dev:latest" already present on machine and can be accessed by the pod
envoy-gateway-system      29m         Normal    Created                            pod/envoy-mcp-system-mcp-gateway-7ead7c3d-5fb5c8bd9b-8dm77       Container created
envoy-gateway-system      29m         Normal    Started                            pod/envoy-mcp-system-mcp-gateway-7ead7c3d-5fb5c8bd9b-8dm77       Container started
envoy-gateway-system      29m         Normal    ScalingReplicaSet                  deployment/envoy-mcp-system-mcp-gateway-7ead7c3d                 Scaled down replica set envoy-mcp-system-mcp-gateway-7ead7c3d-8545c8b4d7 from 1 to 0
envoy-gateway-system      29m         Normal    SuccessfulDelete                   replicaset/envoy-mcp-system-mcp-gateway-7ead7c3d-8545c8b4d7      Deleted pod: envoy-mcp-system-mcp-gateway-7ead7c3d-8545c8b4d7-k2zft
envoy-gateway-system      29m         Normal    Killing                            pod/envoy-mcp-system-mcp-gateway-7ead7c3d-8545c8b4d7-k2zft       Stopping container shutdown-manager
envoy-gateway-system      29m         Normal    Killing                            pod/envoy-mcp-system-mcp-gateway-7ead7c3d-8545c8b4d7-k2zft       Stopping container envoy
monitoring                29m         Normal    Pulling                            pod/alertmanager-7d8c7db59d-vj5nr                                Pulling image "prom/alertmanager:latest"
monitoring                29m         Normal    ScalingReplicaSet                  deployment/alertmanager                                          Scaled up replica set alertmanager-7d8c7db59d from 0 to 1
monitoring                29m         Normal    Scheduled                          pod/alertmanager-7d8c7db59d-vj5nr                                Successfully assigned monitoring/alertmanager-7d8c7db59d-vj5nr to kubernaut-hub-control-plane
monitoring                29m         Normal    SuccessfulCreate                   replicaset/alertmanager-7d8c7db59d                               Created pod: alertmanager-7d8c7db59d-vj5nr
prometheus-operator       29m         Normal    SuccessfulCreate                   job/prometheus-operator-kube-p-admission-create                  Created pod: prometheus-operator-kube-p-admission-create-5bhtx
prometheus-operator       29m         Normal    Scheduled                          pod/prometheus-operator-kube-p-admission-create-5bhtx            Successfully assigned prometheus-operator/prometheus-operator-kube-p-admission-create-5bhtx to kubernaut-hub-control-plane
monitoring                29m         Normal    Started                            pod/alertmanager-7d8c7db59d-vj5nr                                Container started
monitoring                29m         Normal    Pulled                             pod/alertmanager-7d8c7db59d-vj5nr                                Successfully pulled image "prom/alertmanager:latest" in 5.355s (5.355s including waiting). Image size: 37767509 bytes.
monitoring                29m         Normal    Created                            pod/alertmanager-7d8c7db59d-vj5nr                                Container created
prometheus-operator       29m         Normal    Pulling                            pod/prometheus-operator-kube-p-admission-create-5bhtx            Pulling image "ghcr.io/jkroepke/kube-webhook-certgen:1.8.5"
envoy-gateway-system      29m         Warning   FailedPreStopHook                  pod/envoy-mcp-system-mcp-gateway-7ead7c3d-8545c8b4d7-k2zft       PreStopHook failed
prometheus-operator       29m         Normal    Started                            pod/prometheus-operator-kube-p-admission-create-5bhtx            Container started
prometheus-operator       29m         Normal    Created                            pod/prometheus-operator-kube-p-admission-create-5bhtx            Container created
prometheus-operator       29m         Normal    Pulled                             pod/prometheus-operator-kube-p-admission-create-5bhtx            Successfully pulled image "ghcr.io/jkroepke/kube-webhook-certgen:1.8.5" in 2.046s (2.214s including waiting). Image size: 7968652 bytes.
prometheus-operator       29m         Normal    SuccessfulCreate                   replicaset/prometheus-operator-68dc8988fb                        Created pod: prometheus-operator-68dc8988fb-fssk2
prometheus-operator       29m         Normal    Scheduled                          pod/prometheus-operator-68dc8988fb-fssk2                         Successfully assigned prometheus-operator/prometheus-operator-68dc8988fb-fssk2 to kubernaut-hub-control-plane
prometheus-operator       29m         Normal    Completed                          job/prometheus-operator-kube-p-admission-create                  Job completed
prometheus-operator       29m         Normal    ScalingReplicaSet                  deployment/prometheus-operator                                   Scaled up replica set prometheus-operator-68dc8988fb from 0 to 1
prometheus-operator       29m         Normal    Pulling                            pod/prometheus-operator-68dc8988fb-fssk2                         Pulling image "quay.io/prometheus-operator/prometheus-operator:v0.93.0"
prometheus-operator       29m         Normal    Scheduled                          pod/prometheus-operator-kube-p-admission-patch-7fqhj             Successfully assigned prometheus-operator/prometheus-operator-kube-p-admission-patch-7fqhj to kubernaut-hub-control-plane
prometheus-operator       29m         Normal    Created                            pod/prometheus-operator-kube-p-admission-patch-7fqhj             Container created
prometheus-operator       29m         Normal    SuccessfulCreate                   job/prometheus-operator-kube-p-admission-patch                   Created pod: prometheus-operator-kube-p-admission-patch-7fqhj
prometheus-operator       29m         Normal    Started                            pod/prometheus-operator-kube-p-admission-patch-7fqhj             Container started
prometheus-operator       29m         Normal    Pulled                             pod/prometheus-operator-kube-p-admission-patch-7fqhj             Container image "ghcr.io/jkroepke/kube-webhook-certgen:1.8.5" already present on machine and can be accessed by the pod
prometheus-operator       29m         Normal    Completed                          job/prometheus-operator-kube-p-admission-patch                   Job completed
prometheus-operator       29m         Normal    Created                            pod/prometheus-operator-68dc8988fb-fssk2                         Container created
prometheus-operator       29m         Normal    Pulled                             pod/prometheus-operator-68dc8988fb-fssk2                         Successfully pulled image "quay.io/prometheus-operator/prometheus-operator:v0.93.0" in 6.921s (6.921s including waiting). Image size: 18890907 bytes.
prometheus-operator       29m         Warning   Unhealthy                          pod/prometheus-operator-68dc8988fb-fssk2                         Readiness probe failed: Get "https://10.244.0.21:10250/healthz": dial tcp 10.244.0.21:10250: connect: connection refused
prometheus-operator       29m         Normal    Started                            pod/prometheus-operator-68dc8988fb-fssk2                         Container started
monitoring                29m         Normal    ScalingReplicaSet                  deployment/kube-state-metrics                                    Scaled up replica set kube-state-metrics-78f5b5f8f9 from 0 to 1
default                   29m         Warning   FailedToCreateEndpoint             endpoints/kube-state-metrics                                     Failed to create endpoint for service monitoring/kube-state-metrics: endpoints "kube-state-metrics" already exists
monitoring                29m         Normal    Scheduled                          pod/kube-state-metrics-78f5b5f8f9-5t99b                          Successfully assigned monitoring/kube-state-metrics-78f5b5f8f9-5t99b to kubernaut-hub-control-plane
monitoring                29m         Normal    Pulling                            pod/kube-state-metrics-78f5b5f8f9-5t99b                          Pulling image "registry.k8s.io/kube-state-metrics/kube-state-metrics:v2.13.0"
monitoring                29m         Normal    SuccessfulCreate                   replicaset/kube-state-metrics-78f5b5f8f9                         Created pod: kube-state-metrics-78f5b5f8f9-5t99b
monitoring                29m         Normal    Created                            pod/kube-state-metrics-78f5b5f8f9-5t99b                          Container created
monitoring                29m         Normal    Started                            pod/kube-state-metrics-78f5b5f8f9-5t99b                          Container started
monitoring                29m         Normal    Pulled                             pod/kube-state-metrics-78f5b5f8f9-5t99b                          Successfully pulled image "registry.k8s.io/kube-state-metrics/kube-state-metrics:v2.13.0" in 2.191s (2.191s including waiting). Image size: 13123973 bytes.
monitoring                29m         Normal    SuccessfulCreate                   statefulset/prometheus-fleet-spoke                               Create Pod prometheus-fleet-spoke-0 in StatefulSet prometheus-fleet-spoke successful
monitoring                29m         Normal    Scheduled                          pod/prometheus-fleet-spoke-0                                     Successfully assigned monitoring/prometheus-fleet-spoke-0 to kubernaut-hub-control-plane
monitoring                29m         Normal    Pulling                            pod/prometheus-fleet-spoke-0                                     Pulling image "quay.io/prometheus-operator/prometheus-config-reloader:v0.93.0"
monitoring                29m         Normal    Pulled                             pod/prometheus-fleet-spoke-0                                     Successfully pulled image "quay.io/prometheus-operator/prometheus-config-reloader:v0.93.0" in 4.697s (4.697s including waiting). Image size: 13032467 bytes.
monitoring                29m         Normal    Created                            pod/prometheus-fleet-spoke-0                                     Container created
monitoring                29m         Normal    Started                            pod/prometheus-fleet-spoke-0                                     Container started
monitoring                29m         Normal    Pulling                            pod/prometheus-fleet-spoke-0                                     Pulling image "prom/prometheus:latest"
monitoring                28m         Normal    Pulling                            pod/prometheus-fleet-spoke-0                                     Pulling image "quay.io/thanos/thanos:v0.37.2"
monitoring                28m         Normal    Created                            pod/prometheus-fleet-spoke-0                                     Container created
monitoring                28m         Normal    Started                            pod/prometheus-fleet-spoke-0                                     Container started
monitoring                28m         Normal    Pulled                             pod/prometheus-fleet-spoke-0                                     Container image "quay.io/prometheus-operator/prometheus-config-reloader:v0.93.0" already present on machine and can be accessed by the pod
monitoring                28m         Normal    Created                            pod/prometheus-fleet-spoke-0                                     Container created
monitoring                28m         Normal    Started                            pod/prometheus-fleet-spoke-0                                     Container started
monitoring                28m         Normal    Pulled                             pod/prometheus-fleet-spoke-0                                     Successfully pulled image "prom/prometheus:latest" in 11.666s (11.666s including waiting). Image size: 104819933 bytes.
monitoring                28m         Normal    Started                            pod/prometheus-fleet-spoke-0                                     Container started
monitoring                28m         Normal    Created                            pod/prometheus-fleet-spoke-0                                     Container created
monitoring                28m         Normal    Pulled                             pod/prometheus-fleet-spoke-0                                     Successfully pulled image "quay.io/thanos/thanos:v0.37.2" in 8.156s (8.156s including waiting). Image size: 91152135 bytes.
monitoring                27m         Normal    Scheduled                          pod/thanos-querier-644dd96655-qg7fl                              Successfully assigned monitoring/thanos-querier-644dd96655-qg7fl to kubernaut-hub-control-plane
monitoring                27m         Normal    Pulled                             pod/thanos-querier-644dd96655-qg7fl                              Container image "quay.io/thanos/thanos:v0.37.2" already present on machine and can be accessed by the pod
monitoring                27m         Normal    Created                            pod/thanos-querier-644dd96655-qg7fl                              Container created
monitoring                27m         Normal    SuccessfulCreate                   replicaset/thanos-querier-644dd96655                             Created pod: thanos-querier-644dd96655-qg7fl
monitoring                27m         Normal    ScalingReplicaSet                  deployment/thanos-querier                                        Scaled up replica set thanos-querier-644dd96655 from 0 to 1
monitoring                27m         Normal    Started                            pod/thanos-querier-644dd96655-qg7fl                              Container started
kubernaut-system          27m         Normal    SuccessfulCreate                   job/kubernaut-tls-cert-gen                                       Created pod: kubernaut-tls-cert-gen-gzscw
kubernaut-system          27m         Normal    Scheduled                          pod/kubernaut-tls-cert-gen-gzscw                                 Successfully assigned kubernaut-system/kubernaut-tls-cert-gen-gzscw to kubernaut-hub-control-plane
kubernaut-system          27m         Normal    Pulling                            pod/kubernaut-tls-cert-gen-gzscw                                 Pulling image "docker.io/bitnami/kubectl:latest@sha256:6e2cdb22d6ab7264ea198c717f555e30536b54029d26c8781b9f25f78951b564"
kubernaut-system          27m         Normal    Pulled                             pod/kubernaut-tls-cert-gen-gzscw                                 Successfully pulled image "docker.io/bitnami/kubectl:latest@sha256:6e2cdb22d6ab7264ea198c717f555e30536b54029d26c8781b9f25f78951b564" in 8.416s (8.416s including waiting). Image size: 71257358 bytes.
kubernaut-system          27m         Normal    Started                            pod/kubernaut-tls-cert-gen-gzscw                                 Container started
kubernaut-system          27m         Normal    Created                            pod/kubernaut-tls-cert-gen-gzscw                                 Container created
kubernaut-system          27m         Normal    ScalingReplicaSet                  deployment/workflowexecution-controller                          Scaled up replica set workflowexecution-controller-c7bb9b96d from 0 to 1
kubernaut-system          27m         Normal    NoPods                             poddisruptionbudget/console                                      No matching pods found
kubernaut-system          27m         Normal    NoPods                             poddisruptionbudget/datastorage                                  No matching pods found
kubernaut-system          27m         Normal    ScalingReplicaSet                  deployment/datastorage                                           Scaled up replica set datastorage-84bb6d8f5c from 0 to 1
kubernaut-system          27m         Normal    ScalingReplicaSet                  deployment/valkey                                                Scaled up replica set valkey-5695d478b9 from 0 to 1
kubernaut-system          27m         Normal    Completed                          job/kubernaut-tls-cert-gen                                       Job completed
kubernaut-system          27m         Normal    SuccessfulCreate                   replicaset/valkey-5695d478b9                                     Created pod: valkey-5695d478b9-pbz8p
kubernaut-system          27m         Normal    WaitForFirstConsumer               persistentvolumeclaim/valkey-data                                waiting for first consumer to be created before binding
kubernaut-system          27m         Normal    SuccessfulCreate                   replicaset/workflowexecution-controller-c7bb9b96d                Created pod: workflowexecution-controller-c7bb9b96d-6spjh
kubernaut-system          27m         Normal    NoPods                             poddisruptionbudget/workflowexecution-controller                 No matching pods found
kubernaut-system          27m         Normal    SuccessfulCreate                   replicaset/datastorage-84bb6d8f5c                                Created pod: datastorage-84bb6d8f5c-6z962
kubernaut-system          27m         Normal    NoPods                             poddisruptionbudget/notification-controller                      No matching pods found
kubernaut-system          27m         Normal    NoPods                             poddisruptionbudget/remediationorchestrator-controller           No matching pods found
kubernaut-system          27m         Normal    NoPods                             poddisruptionbudget/effectivenessmonitor-controller              No matching pods found
kubernaut-system          27m         Normal    NoPods                             poddisruptionbudget/kubernaut-agent                              No matching pods found
kubernaut-system          27m         Normal    NoPods                             poddisruptionbudget/fleetmetadatacache                           No matching pods found
kubernaut-system          27m         Normal    NoPods                             poddisruptionbudget/signalprocessing-controller                  No matching pods found
kubernaut-system          27m         Normal    SuccessfulCreate                   replicaset/aianalysis-controller-8558694cb9                      Created pod: aianalysis-controller-8558694cb9-lbxks
kubernaut-system          27m         Normal    ScalingReplicaSet                  deployment/authwebhook                                           Scaled up replica set authwebhook-687bf89769 from 0 to 1
kubernaut-system          27m         Normal    NoPods                             poddisruptionbudget/authwebhook                                  No matching pods found
kubernaut-system          27m         Normal    WaitForFirstConsumer               persistentvolumeclaim/postgresql-data                            waiting for first consumer to be created before binding
kubernaut-system          27m         Normal    NoPods                             poddisruptionbudget/apifrontend                                  No matching pods found
kubernaut-system          27m         Normal    ScalingReplicaSet                  deployment/aianalysis-controller                                 Scaled up replica set aianalysis-controller-8558694cb9 from 0 to 1
kubernaut-system          27m         Normal    NoPods                             poddisruptionbudget/aianalysis-controller                        No matching pods found
kubernaut-system          27m         Normal    Scheduled                          pod/workflowexecution-controller-c7bb9b96d-6spjh                 Successfully assigned kubernaut-system/workflowexecution-controller-c7bb9b96d-6spjh to kubernaut-hub-control-plane
kubernaut-system          27m         Normal    SuccessfulCreate                   replicaset/authwebhook-687bf89769                                Created pod: authwebhook-687bf89769-ncm2g
kubernaut-system          27m         Normal    Scheduled                          pod/kubernaut-agent-5d495d7fc-5x6q4                              Successfully assigned kubernaut-system/kubernaut-agent-5d495d7fc-5x6q4 to kubernaut-hub-control-plane
kubernaut-system          27m         Normal    SuccessfulCreate                   replicaset/kubernaut-agent-5d495d7fc                             Created pod: kubernaut-agent-5d495d7fc-5x6q4
kubernaut-system          27m         Normal    ScalingReplicaSet                  deployment/postgresql                                            Scaled up replica set postgresql-64f6569d48 from 0 to 1
kubernaut-system          27m         Normal    ScalingReplicaSet                  deployment/remediationorchestrator-controller                    Scaled up replica set remediationorchestrator-controller-5dbcb769f5 from 0 to 1
kubernaut-system          27m         Normal    Scheduled                          pod/aianalysis-controller-8558694cb9-lbxks                       Successfully assigned kubernaut-system/aianalysis-controller-8558694cb9-lbxks to kubernaut-hub-control-plane
kubernaut-system          27m         Normal    Scheduled                          pod/datastorage-84bb6d8f5c-6z962                                 Successfully assigned kubernaut-system/datastorage-84bb6d8f5c-6z962 to kubernaut-hub-control-plane
kubernaut-system          27m         Normal    Scheduled                          pod/apifrontend-64dfd494b9-tccms                                 Successfully assigned kubernaut-system/apifrontend-64dfd494b9-tccms to kubernaut-hub-control-plane
kubernaut-system          27m         Normal    ScalingReplicaSet                  deployment/notification-controller                               Scaled up replica set notification-controller-5cbf768644 from 0 to 1
kubernaut-system          27m         Normal    ScalingReplicaSet                  deployment/kubernaut-agent                                       Scaled up replica set kubernaut-agent-5d495d7fc from 0 to 1
kubernaut-system          27m         Normal    ScalingReplicaSet                  deployment/fleetmetadatacache                                    Scaled up replica set fleetmetadatacache-d4dd6c7f8 from 0 to 1
kubernaut-system          27m         Normal    SuccessfulCreate                   replicaset/fleetmetadatacache-d4dd6c7f8                          Created pod: fleetmetadatacache-d4dd6c7f8-88xcg
kubernaut-system          27m         Normal    Scheduled                          pod/fleetmetadatacache-d4dd6c7f8-88xcg                           Successfully assigned kubernaut-system/fleetmetadatacache-d4dd6c7f8-88xcg to kubernaut-hub-control-plane
kubernaut-system          27m         Normal    ScalingReplicaSet                  deployment/effectivenessmonitor-controller                       Scaled up replica set effectivenessmonitor-controller-cb7d95bb6 from 0 to 1
kubernaut-system          27m         Normal    SuccessfulCreate                   replicaset/apifrontend-64dfd494b9                                Created pod: apifrontend-64dfd494b9-tccms
kubernaut-system          27m         Normal    SuccessfulCreate                   replicaset/effectivenessmonitor-controller-cb7d95bb6             Created pod: effectivenessmonitor-controller-cb7d95bb6-xmdss
kubernaut-system          27m         Normal    ScalingReplicaSet                  deployment/apifrontend                                           Scaled up replica set apifrontend-64dfd494b9 from 0 to 1
kubernaut-system          27m         Normal    Scheduled                          pod/authwebhook-687bf89769-ncm2g                                 Successfully assigned kubernaut-system/authwebhook-687bf89769-ncm2g to kubernaut-hub-control-plane
kubernaut-system          27m         Normal    SuccessfulCreate                   replicaset/postgresql-64f6569d48                                 Created pod: postgresql-64f6569d48-gsr68
kubernaut-system          27m         Normal    Scheduled                          pod/effectivenessmonitor-controller-cb7d95bb6-xmdss              Successfully assigned kubernaut-system/effectivenessmonitor-controller-cb7d95bb6-xmdss to kubernaut-hub-control-plane
kubernaut-system          27m         Normal    ExternalProvisioning               persistentvolumeclaim/valkey-data                                Waiting for a volume to be created either by the external provisioner 'rancher.io/local-path' or manually by the system administrator. If volume creation is delayed, please verify that the provisioner is running and correctly registered.
kubernaut-system          27m         Normal    Scheduled                          pod/remediationorchestrator-controller-5dbcb769f5-6h8jr          Successfully assigned kubernaut-system/remediationorchestrator-controller-5dbcb769f5-6h8jr to kubernaut-hub-control-plane
kubernaut-system          27m         Normal    Scheduled                          pod/console-756d955c66-64z77                                     Successfully assigned kubernaut-system/console-756d955c66-64z77 to kubernaut-hub-control-plane
kubernaut-system          27m         Normal    Provisioning                       persistentvolumeclaim/postgresql-data                            External provisioner is provisioning volume for claim "kubernaut-system/postgresql-data"
kubernaut-system          27m         Normal    ExternalProvisioning               persistentvolumeclaim/postgresql-data                            Waiting for a volume to be created either by the external provisioner 'rancher.io/local-path' or manually by the system administrator. If volume creation is delayed, please verify that the provisioner is running and correctly registered.
kubernaut-system          27m         Normal    SuccessfulCreate                   replicaset/notification-controller-5cbf768644                    Created pod: notification-controller-5cbf768644-jn8qv
kubernaut-system          27m         Warning   FailedMount                        pod/authwebhook-687bf89769-ncm2g                                 MountVolume.SetUp failed for volume "config" : failed to sync configmap cache: timed out waiting for the condition
monitoring                27m         Warning   Unhealthy                          pod/thanos-querier-644dd96655-qg7fl                              Readiness probe failed: Get "http://10.244.0.25:9090/-/ready": context deadline exceeded (Client.Timeout exceeded while awaiting headers)
kubernaut-system          27m         Normal    SuccessfulCreate                   replicaset/console-756d955c66                                    Created pod: console-756d955c66-64z77
kubernaut-system          27m         Normal    Scheduled                          pod/notification-controller-5cbf768644-jn8qv                     Successfully assigned kubernaut-system/notification-controller-5cbf768644-jn8qv to kubernaut-hub-control-plane
kubernaut-system          27m         Normal    ScalingReplicaSet                  deployment/console                                               Scaled up replica set console-756d955c66 from 0 to 1
kubernaut-system          27m         Normal    Provisioning                       persistentvolumeclaim/valkey-data                                External provisioner is provisioning volume for claim "kubernaut-system/valkey-data"
kubernaut-system          27m         Normal    ScalingReplicaSet                  deployment/signalprocessing-controller                           Scaled up replica set signalprocessing-controller-69648fdd9c from 0 to 1
kubernaut-system          27m         Normal    SuccessfulCreate                   replicaset/signalprocessing-controller-69648fdd9c                Created pod: signalprocessing-controller-69648fdd9c-rsqzp
kubernaut-system          27m         Normal    Scheduled                          pod/signalprocessing-controller-69648fdd9c-rsqzp                 Successfully assigned kubernaut-system/signalprocessing-controller-69648fdd9c-rsqzp to kubernaut-hub-control-plane
kubernaut-system          27m         Normal    SuccessfulCreate                   replicaset/remediationorchestrator-controller-5dbcb769f5         Created pod: remediationorchestrator-controller-5dbcb769f5-6h8jr
kubernaut-system          27m         Normal    Pulling                            pod/datastorage-84bb6d8f5c-6z962                                 Pulling image "postgres:16-alpine"
kubernaut-system          27m         Normal    Pulling                            pod/aianalysis-controller-8558694cb9-lbxks                       Pulling image "quay.io/kubernaut-ai/aianalysis:1.6.0-rc20"
kubernaut-system          27m         Normal    Pulling                            pod/effectivenessmonitor-controller-cb7d95bb6-xmdss              Pulling image "quay.io/kubernaut-ai/effectivenessmonitor:1.6.0-rc20"
kubernaut-system          27m         Normal    Created                            pod/authwebhook-687bf89769-ncm2g                                 Container created
kubernaut-system          27m         Normal    Pulled                             pod/authwebhook-687bf89769-ncm2g                                 Container image "docker.io/bitnami/kubectl:latest@sha256:6e2cdb22d6ab7264ea198c717f555e30536b54029d26c8781b9f25f78951b564" already present on machine and can be accessed by the pod
kubernaut-system          27m         Normal    Pulling                            pod/kubernaut-agent-5d495d7fc-5x6q4                              Pulling image "quay.io/kubernaut-ai/kubernautagent:1.6.0-rc20"
local-path-storage        27m         Normal    Pulled                             pod/helper-pod-create-pvc-1ec90f4c-d064-4606-93de-f7163e3ecfc7   Container image "docker.io/kindest/local-path-helper:v20260131-7181c60a" already present on machine and can be accessed by the pod
kubernaut-system          27m         Normal    Pulling                            pod/signalprocessing-controller-69648fdd9c-rsqzp                 Pulling image "quay.io/kubernaut-ai/signalprocessing:1.6.0-rc20"
local-path-storage        27m         Normal    Created                            pod/helper-pod-create-pvc-1ec90f4c-d064-4606-93de-f7163e3ecfc7   Container created
kubernaut-system          27m         Normal    Pulling                            pod/apifrontend-64dfd494b9-tccms                                 Pulling image "quay.io/kubernaut-ai/apifrontend:1.6.0-rc20"
kubernaut-system          27m         Normal    Pulling                            pod/remediationorchestrator-controller-5dbcb769f5-6h8jr          Pulling image "quay.io/kubernaut-ai/remediationorchestrator:1.6.0-rc20"
local-path-storage        27m         Normal    Created                            pod/helper-pod-create-pvc-66d04af6-a9d4-49ef-944e-fd8d0834ba7d   Container created
kubernaut-system          27m         Normal    Pulling                            pod/notification-controller-5cbf768644-jn8qv                     Pulling image "quay.io/kubernaut-ai/notification:1.6.0-rc20"
local-path-storage        27m         Normal    Started                            pod/helper-pod-create-pvc-1ec90f4c-d064-4606-93de-f7163e3ecfc7   Container started
kubernaut-system          27m         Normal    Pulling                            pod/workflowexecution-controller-c7bb9b96d-6spjh                 Pulling image "quay.io/kubernaut-ai/workflowexecution:1.6.0-rc20"
local-path-storage        27m         Normal    Pulled                             pod/helper-pod-create-pvc-66d04af6-a9d4-49ef-944e-fd8d0834ba7d   Container image "docker.io/kindest/local-path-helper:v20260131-7181c60a" already present on machine and can be accessed by the pod
kubernaut-system          27m         Normal    Pulling                            pod/console-756d955c66-64z77                                     Pulling image "quay.io/oauth2-proxy/oauth2-proxy:v7.15.3"
local-path-storage        27m         Normal    Started                            pod/helper-pod-create-pvc-66d04af6-a9d4-49ef-944e-fd8d0834ba7d   Container started
kubernaut-system          27m         Normal    Pulling                            pod/fleetmetadatacache-d4dd6c7f8-88xcg                           Pulling image "quay.io/kubernaut-ai/fleetmetadatacache:1.6.0-rc20"
kubernaut-system          27m         Normal    Started                            pod/authwebhook-687bf89769-ncm2g                                 Container started
kubernaut-system          27m         Normal    ProvisioningSucceeded              persistentvolumeclaim/postgresql-data                            Successfully provisioned volume pvc-66d04af6-a9d4-49ef-944e-fd8d0834ba7d
kubernaut-system          27m         Normal    Pulling                            pod/kubernaut-db-migration-rw2sp                                 Pulling image "quay.io/kubernaut-ai/db-migrate:1.6.0-rc20"
kubernaut-system          27m         Normal    SuccessfulCreate                   job/kubernaut-db-migration                                       Created pod: kubernaut-db-migration-rw2sp
kubernaut-system          27m         Normal    Pulling                            pod/postgresql-64f6569d48-gsr68                                  Pulling image "postgres:16-alpine"
kubernaut-system          27m         Normal    Scheduled                          pod/postgresql-64f6569d48-gsr68                                  Successfully assigned kubernaut-system/postgresql-64f6569d48-gsr68 to kubernaut-hub-control-plane
kubernaut-system          27m         Normal    Scheduled                          pod/kubernaut-db-migration-rw2sp                                 Successfully assigned kubernaut-system/kubernaut-db-migration-rw2sp to kubernaut-hub-control-plane
kubernaut-system          27m         Normal    Scheduled                          pod/valkey-5695d478b9-pbz8p                                      Successfully assigned kubernaut-system/valkey-5695d478b9-pbz8p to kubernaut-hub-control-plane
kubernaut-system          27m         Normal    Pulling                            pod/valkey-5695d478b9-pbz8p                                      Pulling image "valkey/valkey:8-alpine"
kubernaut-system          27m         Normal    ProvisioningSucceeded              persistentvolumeclaim/valkey-data                                Successfully provisioned volume pvc-1ec90f4c-d064-4606-93de-f7163e3ecfc7
kubernaut-system          27m         Normal    Pulling                            pod/authwebhook-687bf89769-ncm2g                                 Pulling image "quay.io/kubernaut-ai/authwebhook:1.6.0-rc20"
kubernaut-system          26m         Normal    Pulled                             pod/datastorage-84bb6d8f5c-6z962                                 Successfully pulled image "postgres:16-alpine" in 20.104s (20.106s including waiting). Image size: 113905390 bytes.
kubernaut-system          26m         Normal    Created                            pod/datastorage-84bb6d8f5c-6z962                                 Container created
kubernaut-system          26m         Normal    Started                            pod/datastorage-84bb6d8f5c-6z962                                 Container started
kubernaut-system          26m         Normal    Pulled                             pod/aianalysis-controller-8558694cb9-lbxks                       Successfully pulled image "quay.io/kubernaut-ai/aianalysis:1.6.0-rc20" in 5.26s (23.785s including waiting). Image size: 16037041 bytes.
kubernaut-system          26m         Normal    Started                            pod/aianalysis-controller-8558694cb9-lbxks                       Container started
kubernaut-system          26m         Normal    Created                            pod/aianalysis-controller-8558694cb9-lbxks                       Container created
kubernaut-system          26m         Normal    Created                            pod/apifrontend-64dfd494b9-tccms                                 Container created
kubernaut-system          26m         Normal    Pulled                             pod/apifrontend-64dfd494b9-tccms                                 Successfully pulled image "quay.io/kubernaut-ai/apifrontend:1.6.0-rc20" in 5.913s (29.481s including waiting). Image size: 28175597 bytes.
kubernaut-system          26m         Normal    Started                            pod/apifrontend-64dfd494b9-tccms                                 Container started
kubernaut-system          26m         Normal    Created                            pod/workflowexecution-controller-c7bb9b96d-6spjh                 Container created
kubernaut-system          26m         Normal    Started                            pod/workflowexecution-controller-c7bb9b96d-6spjh                 Container started
kubernaut-system          26m         Normal    Pulled                             pod/workflowexecution-controller-c7bb9b96d-6spjh                 Successfully pulled image "quay.io/kubernaut-ai/workflowexecution:1.6.0-rc20" in 5.314s (34.612s including waiting). Image size: 21235409 bytes.
kubernaut-system          26m         Warning   Unhealthy                          pod/apifrontend-64dfd494b9-tccms                                 Startup probe failed: Get "http://10.244.0.31:8081/healthz": dial tcp 10.244.0.31:8081: connect: connection refused
kubernaut-system          26m         Normal    Created                            pod/effectivenessmonitor-controller-cb7d95bb6-xmdss              Container created
kubernaut-system          26m         Normal    Started                            pod/effectivenessmonitor-controller-cb7d95bb6-xmdss              Container started
kubernaut-system          26m         Normal    Pulled                             pod/effectivenessmonitor-controller-cb7d95bb6-xmdss              Successfully pulled image "quay.io/kubernaut-ai/effectivenessmonitor:1.6.0-rc20" in 4.776s (39.365s including waiting). Image size: 13661590 bytes.
kubernaut-system          26m         Normal    Started                            pod/remediationorchestrator-controller-5dbcb769f5-6h8jr          Container started
kubernaut-system          26m         Normal    Pulled                             pod/remediationorchestrator-controller-5dbcb769f5-6h8jr          Successfully pulled image "quay.io/kubernaut-ai/remediationorchestrator:1.6.0-rc20" in 4.416s (43.679s including waiting). Image size: 13913627 bytes.
kubernaut-system          26m         Normal    Created                            pod/remediationorchestrator-controller-5dbcb769f5-6h8jr          Container created
kubernaut-system          26m         Normal    Created                            pod/kubernaut-agent-5d495d7fc-5x6q4                              Container created
kubernaut-system          26m         Normal    Started                            pod/kubernaut-agent-5d495d7fc-5x6q4                              Container started
kubernaut-system          26m         Normal    Pulled                             pod/kubernaut-agent-5d495d7fc-5x6q4                              Successfully pulled image "quay.io/kubernaut-ai/kubernautagent:1.6.0-rc20" in 5.281s (48.912s including waiting). Image size: 26006126 bytes.
kubernaut-system          26m         Normal    Created                            pod/notification-controller-5cbf768644-jn8qv                     Container created
kubernaut-system          26m         Normal    Pulled                             pod/notification-controller-5cbf768644-jn8qv                     Successfully pulled image "quay.io/kubernaut-ai/notification:1.6.0-rc20" in 5.645s (54.554s including waiting). Image size: 13056132 bytes.
kubernaut-system          26m         Normal    Started                            pod/notification-controller-5cbf768644-jn8qv                     Container started
kubernaut-system          26m         Normal    Started                            pod/signalprocessing-controller-69648fdd9c-rsqzp                 Container started
kubernaut-system          26m         Normal    Created                            pod/signalprocessing-controller-69648fdd9c-rsqzp                 Container created
kubernaut-system          26m         Normal    Pulled                             pod/signalprocessing-controller-69648fdd9c-rsqzp                 Successfully pulled image "quay.io/kubernaut-ai/signalprocessing:1.6.0-rc20" in 5.457s (59.849s including waiting). Image size: 16479609 bytes.
kubernaut-system          26m         Normal    Pulled                             pod/console-756d955c66-64z77                                     Successfully pulled image "quay.io/oauth2-proxy/oauth2-proxy:v7.15.3" in 5.342s (1m5.055s including waiting). Image size: 18252499 bytes.
kubernaut-system          26m         Normal    Created                            pod/console-756d955c66-64z77                                     Container created
kubernaut-system          26m         Normal    Started                            pod/console-756d955c66-64z77                                     Container started
kubernaut-system          26m         Normal    Pulling                            pod/console-756d955c66-64z77                                     Pulling image "quay.io/kubernaut-ai/kubernaut-console:1.6.0-rc20"
kubernaut-system          25m         Normal    Started                            pod/fleetmetadatacache-d4dd6c7f8-88xcg                           Container started
kubernaut-system          25m         Normal    Created                            pod/fleetmetadatacache-d4dd6c7f8-88xcg                           Container created
kubernaut-system          25m         Normal    Pulled                             pod/fleetmetadatacache-d4dd6c7f8-88xcg                           Successfully pulled image "quay.io/kubernaut-ai/fleetmetadatacache:1.6.0-rc20" in 4.432s (1m9.365s including waiting). Image size: 11658904 bytes.
kubernaut-system          25m         Normal    Created                            pod/valkey-5695d478b9-pbz8p                                      Container created
kubernaut-system          25m         Normal    Pulled                             pod/valkey-5695d478b9-pbz8p                                      Successfully pulled image "valkey/valkey:8-alpine" in 3.73s (1m10.31s including waiting). Image size: 17940082 bytes.
kubernaut-system          25m         Normal    Created                            pod/postgresql-64f6569d48-gsr68                                  Container created
kubernaut-system          25m         Normal    Started                            pod/valkey-5695d478b9-pbz8p                                      Container started
kubernaut-system          25m         Normal    Started                            pod/postgresql-64f6569d48-gsr68                                  Container started
kubernaut-system          25m         Normal    Pulled                             pod/postgresql-64f6569d48-gsr68                                  Successfully pulled image "postgres:16-alpine" in 323ms (1m10.314s including waiting). Image size: 113905390 bytes.
kubernaut-system          25m         Warning   Unhealthy                          pod/fleetmetadatacache-d4dd6c7f8-88xcg                           Readiness probe failed: Get "http://10.244.0.40:8081/readyz": context deadline exceeded (Client.Timeout exceeded while awaiting headers)
kubernaut-system          25m         Normal    Created                            pod/kubernaut-db-migration-rw2sp                                 Container created
kubernaut-system          25m         Normal    Started                            pod/kubernaut-db-migration-rw2sp                                 Container started
kubernaut-system          25m         Normal    Pulled                             pod/kubernaut-db-migration-rw2sp                                 Successfully pulled image "quay.io/kubernaut-ai/db-migrate:1.6.0-rc20" in 6.924s (1m17.196s including waiting). Image size: 52131622 bytes.
kubernaut-system          25m         Normal    Pulling                            pod/datastorage-84bb6d8f5c-6z962                                 Pulling image "quay.io/kubernaut-ai/datastorage:1.6.0-rc20"
kubernaut-system          25m         Normal    Started                            pod/authwebhook-687bf89769-ncm2g                                 Container started
kubernaut-system          25m         Normal    Created                            pod/authwebhook-687bf89769-ncm2g                                 Container created
kubernaut-system          25m         Normal    Pulled                             pod/authwebhook-687bf89769-ncm2g                                 Successfully pulled image "quay.io/kubernaut-ai/authwebhook:1.6.0-rc20" in 4.014s (1m19.774s including waiting). Image size: 13129009 bytes.
kubernaut-system          25m         Normal    Started                            pod/kubernaut-db-migration-rw2sp                                 Container started
kubernaut-system          25m         Normal    Created                            pod/kubernaut-db-migration-rw2sp                                 Container created
kubernaut-system          25m         Normal    Pulled                             pod/kubernaut-db-migration-rw2sp                                 Container image "quay.io/kubernaut-ai/db-migrate:1.6.0-rc20" already present on machine and can be accessed by the pod
kubernaut-system          25m         Normal    Completed                          job/kubernaut-db-migration                                       Job completed
kubernaut-system          25m         Normal    SuccessfulCreate                   job/kubernaut-tls-cabundle-patch                                 Created pod: kubernaut-tls-cabundle-patch-hqbx6
kubernaut-system          25m         Normal    Scheduled                          pod/kubernaut-tls-cabundle-patch-hqbx6                           Successfully assigned kubernaut-system/kubernaut-tls-cabundle-patch-hqbx6 to kubernaut-hub-control-plane
kubernaut-system          25m         Normal    Pulling                            pod/kubernaut-tls-cabundle-patch-hqbx6                           Pulling image "docker.io/bitnami/kubectl:latest@sha256:6e2cdb22d6ab7264ea198c717f555e30536b54029d26c8781b9f25f78951b564"
kubernaut-system          25m         Normal    Created                            pod/console-756d955c66-64z77                                     Container created
kubernaut-system          25m         Normal    Pulled                             pod/console-756d955c66-64z77                                     Successfully pulled image "quay.io/kubernaut-ai/kubernaut-console:1.6.0-rc20" in 17.04s (36.214s including waiting). Image size: 114072285 bytes.
kubernaut-system          25m         Normal    Started                            pod/console-756d955c66-64z77                                     Container started
kubernaut-system          25m         Normal    Created                            pod/datastorage-84bb6d8f5c-6z962                                 Container created
kubernaut-system          25m         Normal    Started                            pod/datastorage-84bb6d8f5c-6z962                                 Container started
kubernaut-system          25m         Normal    Pulled                             pod/datastorage-84bb6d8f5c-6z962                                 Successfully pulled image "quay.io/kubernaut-ai/datastorage:1.6.0-rc20" in 5.393s (24.876s including waiting). Image size: 21603526 bytes.
kubernaut-system          25m         Normal    Pulled                             pod/kubernaut-tls-cabundle-patch-hqbx6                           Successfully pulled image "docker.io/bitnami/kubectl:latest@sha256:6e2cdb22d6ab7264ea198c717f555e30536b54029d26c8781b9f25f78951b564" in 398ms (10.521s including waiting). Image size: 71257358 bytes.
kubernaut-system          25m         Normal    Created                            pod/kubernaut-tls-cabundle-patch-hqbx6                           Container created
kubernaut-system          25m         Normal    Started                            pod/kubernaut-tls-cabundle-patch-hqbx6                           Container started
kubernaut-system          25m         Normal    Completed                          job/kubernaut-tls-cabundle-patch                                 Job completed
kubernaut-system          24m         Warning   Unhealthy                          pod/remediationorchestrator-controller-5dbcb769f5-6h8jr          Readiness probe failed: HTTP probe failed with statuscode: 500
kubernaut-system          24m         Warning   Unhealthy                          pod/workflowexecution-controller-c7bb9b96d-6spjh                 Readiness probe failed: HTTP probe failed with statuscode: 500
kubernaut-system          24m         Warning   Unhealthy                          pod/effectivenessmonitor-controller-cb7d95bb6-xmdss              Readiness probe failed: HTTP probe failed with statuscode: 500
kubernaut-system          24m         Warning   Unhealthy                          pod/authwebhook-687bf89769-ncm2g                                 Readiness probe failed: HTTP probe failed with statuscode: 500
kubernaut-system          24m         Warning   Unhealthy                          pod/kubernaut-agent-5d495d7fc-5x6q4                              Readiness probe failed: HTTP probe failed with statuscode: 503
kubernaut-system          24m         Warning   Unhealthy                          pod/aianalysis-controller-8558694cb9-lbxks                       Readiness probe failed: HTTP probe failed with statuscode: 500
kubernaut-system          24m         Warning   Unhealthy                          pod/notification-controller-5cbf768644-jn8qv                     Readiness probe failed: HTTP probe failed with statuscode: 500
kubernaut-system          24m         Warning   Unhealthy                          pod/signalprocessing-controller-69648fdd9c-rsqzp                 Readiness probe failed: HTTP probe failed with statuscode: 500
kubernaut-system          24m         Warning   Unhealthy                          pod/apifrontend-64dfd494b9-tccms                                 Readiness probe failed: HTTP probe failed with statuscode: 503
gitea                     22m         Normal    WaitForFirstConsumer               persistentvolumeclaim/valkey-data-gitea-valkey-cluster-1         waiting for first consumer to be created before binding
gitea                     22m         Normal    ExternalProvisioning               persistentvolumeclaim/valkey-data-gitea-valkey-cluster-2         Waiting for a volume to be created either by the external provisioner 'rancher.io/local-path' or manually by the system administrator. If volume creation is delayed, please verify that the provisioner is running and correctly registered.
gitea                     22m         Normal    Provisioning                       persistentvolumeclaim/valkey-data-gitea-valkey-cluster-0         External provisioner is provisioning volume for claim "gitea/valkey-data-gitea-valkey-cluster-0"
gitea                     22m         Normal    NoPods                             poddisruptionbudget/gitea-valkey-cluster                         No matching pods found
gitea                     22m         Normal    SuccessfulCreate                   replicaset/gitea-558d87855d                                      Created pod: gitea-558d87855d-59g9f
local-path-storage        22m         Normal    Pulled                             pod/helper-pod-create-pvc-d426cbf2-2ae6-4743-be85-ad3c29c9d071   Container image "docker.io/kindest/local-path-helper:v20260131-7181c60a" already present on machine and can be accessed by the pod
gitea                     22m         Normal    WaitForFirstConsumer               persistentvolumeclaim/valkey-data-gitea-valkey-cluster-0         waiting for first consumer to be created before binding
gitea                     22m         Normal    ExternalProvisioning               persistentvolumeclaim/valkey-data-gitea-valkey-cluster-1         Waiting for a volume to be created either by the external provisioner 'rancher.io/local-path' or manually by the system administrator. If volume creation is delayed, please verify that the provisioner is running and correctly registered.
gitea                     22m         Normal    SuccessfulCreate                   statefulset/gitea-valkey-cluster                                 Create Pod gitea-valkey-cluster-1 in StatefulSet gitea-valkey-cluster successful
gitea                     22m         Normal    SuccessfulCreate                   statefulset/gitea-valkey-cluster                                 Create Claim valkey-data-gitea-valkey-cluster-1 Pod gitea-valkey-cluster-1 in StatefulSet gitea-valkey-cluster success
gitea                     22m         Normal    SuccessfulCreate                   statefulset/gitea-valkey-cluster                                 Create Pod gitea-valkey-cluster-2 in StatefulSet gitea-valkey-cluster successful
gitea                     22m         Normal    SuccessfulCreate                   statefulset/gitea-valkey-cluster                                 Create Claim valkey-data-gitea-valkey-cluster-2 Pod gitea-valkey-cluster-2 in StatefulSet gitea-valkey-cluster success
gitea                     22m         Normal    SuccessfulCreate                   statefulset/gitea-valkey-cluster                                 Create Pod gitea-valkey-cluster-0 in StatefulSet gitea-valkey-cluster successful
gitea                     22m         Normal    Provisioning                       persistentvolumeclaim/valkey-data-gitea-valkey-cluster-1         External provisioner is provisioning volume for claim "gitea/valkey-data-gitea-valkey-cluster-1"
gitea                     22m         Normal    WaitForFirstConsumer               persistentvolumeclaim/valkey-data-gitea-valkey-cluster-2         waiting for first consumer to be created before binding
gitea                     22m         Normal    ExternalProvisioning               persistentvolumeclaim/valkey-data-gitea-valkey-cluster-0         Waiting for a volume to be created either by the external provisioner 'rancher.io/local-path' or manually by the system administrator. If volume creation is delayed, please verify that the provisioner is running and correctly registered.
gitea                     22m         Normal    Provisioning                       persistentvolumeclaim/valkey-data-gitea-valkey-cluster-2         External provisioner is provisioning volume for claim "gitea/valkey-data-gitea-valkey-cluster-2"
gitea                     22m         Normal    SuccessfulCreate                   statefulset/gitea-valkey-cluster                                 Create Claim valkey-data-gitea-valkey-cluster-0 Pod gitea-valkey-cluster-0 in StatefulSet gitea-valkey-cluster success
gitea                     22m         Normal    Pulling                            pod/gitea-558d87855d-59g9f                                       Pulling image "docker.gitea.com/gitea:1.27.0-rootless"
gitea                     22m         Normal    Scheduled                          pod/gitea-558d87855d-59g9f                                       Successfully assigned gitea/gitea-558d87855d-59g9f to kubernaut-hub-control-plane
local-path-storage        22m         Normal    Pulled                             pod/helper-pod-create-pvc-ff3473ab-ea99-45d3-87ca-f936be9e2b6e   Container image "docker.io/kindest/local-path-helper:v20260131-7181c60a" already present on machine and can be accessed by the pod
gitea                     22m         Normal    ScalingReplicaSet                  deployment/gitea                                                 Scaled up replica set gitea-558d87855d from 0 to 1
local-path-storage        22m         Normal    Created                            pod/helper-pod-create-pvc-ff3473ab-ea99-45d3-87ca-f936be9e2b6e   Container created
local-path-storage        22m         Normal    Started                            pod/helper-pod-create-pvc-d426cbf2-2ae6-4743-be85-ad3c29c9d071   Container started
local-path-storage        22m         Normal    Created                            pod/helper-pod-create-pvc-d426cbf2-2ae6-4743-be85-ad3c29c9d071   Container created
local-path-storage        22m         Normal    Started                            pod/helper-pod-create-pvc-ff3473ab-ea99-45d3-87ca-f936be9e2b6e   Container started
local-path-storage        22m         Normal    Pulled                             pod/helper-pod-create-pvc-55ee0eb7-db44-4736-9118-dffb9be8c35d   Container image "docker.io/kindest/local-path-helper:v20260131-7181c60a" already present on machine and can be accessed by the pod
local-path-storage        22m         Normal    Created                            pod/helper-pod-create-pvc-55ee0eb7-db44-4736-9118-dffb9be8c35d   Container created
local-path-storage        22m         Normal    Started                            pod/helper-pod-create-pvc-55ee0eb7-db44-4736-9118-dffb9be8c35d   Container started
gitea                     22m         Normal    ProvisioningSucceeded              persistentvolumeclaim/valkey-data-gitea-valkey-cluster-2         Successfully provisioned volume pvc-ff3473ab-ea99-45d3-87ca-f936be9e2b6e
gitea                     22m         Normal    ProvisioningSucceeded              persistentvolumeclaim/valkey-data-gitea-valkey-cluster-0         Successfully provisioned volume pvc-d426cbf2-2ae6-4743-be85-ad3c29c9d071
gitea                     22m         Normal    Scheduled                          pod/gitea-valkey-cluster-0                                       Successfully assigned gitea/gitea-valkey-cluster-0 to kubernaut-hub-control-plane
gitea                     22m         Normal    Scheduled                          pod/gitea-valkey-cluster-2                                       Successfully assigned gitea/gitea-valkey-cluster-2 to kubernaut-hub-control-plane
gitea                     22m         Normal    Pulling                            pod/gitea-valkey-cluster-2                                       Pulling image "docker.io/bitnamilegacy/valkey-cluster:8.1.3-debian-12-r3"
gitea                     22m         Normal    ProvisioningSucceeded              persistentvolumeclaim/valkey-data-gitea-valkey-cluster-1         Successfully provisioned volume pvc-55ee0eb7-db44-4736-9118-dffb9be8c35d
gitea                     22m         Normal    Pulling                            pod/gitea-valkey-cluster-0                                       Pulling image "docker.io/bitnamilegacy/valkey-cluster:8.1.3-debian-12-r3"
gitea                     22m         Normal    Pulling                            pod/gitea-valkey-cluster-1                                       Pulling image "docker.io/bitnamilegacy/valkey-cluster:8.1.3-debian-12-r3"
gitea                     22m         Normal    Scheduled                          pod/gitea-valkey-cluster-1                                       Successfully assigned gitea/gitea-valkey-cluster-1 to kubernaut-hub-control-plane
gitea                     22m         Normal    Started                            pod/gitea-558d87855d-59g9f                                       Container started
gitea                     22m         Normal    Created                            pod/gitea-558d87855d-59g9f                                       Container created
gitea                     22m         Normal    Pulled                             pod/gitea-558d87855d-59g9f                                       Successfully pulled image "docker.gitea.com/gitea:1.27.0-rootless" in 9.626s (9.626s including waiting). Image size: 65193934 bytes.
gitea                     22m         Normal    Pulled                             pod/gitea-558d87855d-59g9f                                       Container image "docker.gitea.com/gitea:1.27.0-rootless" already present on machine and can be accessed by the pod
gitea                     22m         Normal    Created                            pod/gitea-558d87855d-59g9f                                       Container created
gitea                     22m         Normal    Started                            pod/gitea-558d87855d-59g9f                                       Container started
gitea                     22m         Warning   BackOff                            pod/gitea-558d87855d-59g9f                                       Back-off restarting failed container configure-gitea in pod gitea-558d87855d-59g9f_gitea(ff57244d-7b2b-473e-91c5-887d7c77288d)
gitea                     22m         Normal    Pulled                             pod/gitea-valkey-cluster-2                                       Successfully pulled image "docker.io/bitnamilegacy/valkey-cluster:8.1.3-debian-12-r3" in 12.451s (18.09s including waiting). Image size: 50708844 bytes.
gitea                     22m         Normal    Started                            pod/gitea-valkey-cluster-1                                       Container started
gitea                     22m         Normal    Created                            pod/gitea-valkey-cluster-2                                       Container created
gitea                     22m         Normal    Created                            pod/gitea-valkey-cluster-0                                       Container created
gitea                     22m         Normal    Started                            pod/gitea-valkey-cluster-0                                       Container started
gitea                     22m         Normal    Pulled                             pod/gitea-valkey-cluster-0                                       Successfully pulled image "docker.io/bitnamilegacy/valkey-cluster:8.1.3-debian-12-r3" in 370ms (18.438s including waiting). Image size: 50708844 bytes.
gitea                     22m         Normal    Started                            pod/gitea-valkey-cluster-2                                       Container started
gitea                     22m         Normal    Created                            pod/gitea-valkey-cluster-1                                       Container created
gitea                     22m         Normal    Pulled                             pod/gitea-valkey-cluster-1                                       Successfully pulled image "docker.io/bitnamilegacy/valkey-cluster:8.1.3-debian-12-r3" in 314ms (17.743s including waiting). Image size: 50708844 bytes.
gitea                     22m         Warning   Unhealthy                          pod/gitea-valkey-cluster-2                                       Readiness probe failed: Could not connect to Valkey at localhost:6379: Connection refused
gitea                     22m         Normal    Pulled                             pod/gitea-558d87855d-59g9f                                       Container image "docker.gitea.com/gitea:1.27.0-rootless" already present on machine and can be accessed by the pod
gitea                     22m         Normal    Started                            pod/gitea-558d87855d-59g9f                                       Container started
gitea                     22m         Warning   Unhealthy                          pod/gitea-valkey-cluster-1                                       Readiness probe failed: cluster_state:fail
gitea                     22m         Normal    Created                            pod/gitea-558d87855d-59g9f                                       Container created
gitea                     21m         Normal    Pulled                             pod/gitea-558d87855d-59g9f                                       Container image "docker.gitea.com/gitea:1.27.0-rootless" already present on machine and can be accessed by the pod
gitea                     21m         Normal    Created                            pod/gitea-558d87855d-59g9f                                       Container created
gitea                     21m         Normal    Started                            pod/gitea-558d87855d-59g9f                                       Container started
gitea                     21m         Warning   Unhealthy                          pod/gitea-valkey-cluster-0                                       Readiness probe failed: cluster_state:fail
argocd                    21m         Normal    Scheduled                          pod/argocd-applicationset-controller-7fb7c76f76-ssmwf            Successfully assigned argocd/argocd-applicationset-controller-7fb7c76f76-ssmwf to kubernaut-hub-control-plane
argocd                    21m         Normal    ScalingReplicaSet                  deployment/argocd-dex-server                                     Scaled up replica set argocd-dex-server-7d54f7f9d6 from 0 to 1
argocd                    21m         Normal    Scheduled                          pod/argocd-notifications-controller-7fcfd67447-58kqj             Successfully assigned argocd/argocd-notifications-controller-7fcfd67447-58kqj to kubernaut-hub-control-plane
argocd                    21m         Normal    SuccessfulCreate                   replicaset/argocd-notifications-controller-7fcfd67447            Created pod: argocd-notifications-controller-7fcfd67447-58kqj
argocd                    21m         Normal    ScalingReplicaSet                  deployment/argocd-applicationset-controller                      Scaled up replica set argocd-applicationset-controller-7fb7c76f76 from 0 to 1
argocd                    21m         Normal    SuccessfulCreate                   replicaset/argocd-applicationset-controller-7fb7c76f76           Created pod: argocd-applicationset-controller-7fb7c76f76-ssmwf
argocd                    21m         Normal    ScalingReplicaSet                  deployment/argocd-notifications-controller                       Scaled up replica set argocd-notifications-controller-7fcfd67447 from 0 to 1
argocd                    21m         Normal    Scheduled                          pod/argocd-dex-server-7d54f7f9d6-v77pf                           Successfully assigned argocd/argocd-dex-server-7d54f7f9d6-v77pf to kubernaut-hub-control-plane
argocd                    21m         Normal    SuccessfulCreate                   replicaset/argocd-redis-6bf744486c                               Created pod: argocd-redis-6bf744486c-2ld44
argocd                    21m         Normal    ScalingReplicaSet                  deployment/argocd-server                                         Scaled up replica set argocd-server-665b8b6947 from 0 to 1
argocd                    21m         Normal    ScalingReplicaSet                  deployment/argocd-redis                                          Scaled up replica set argocd-redis-6bf744486c from 0 to 1
argocd                    21m         Normal    Scheduled                          pod/argocd-repo-server-57b98df6c6-tbk5c                          Successfully assigned argocd/argocd-repo-server-57b98df6c6-tbk5c to kubernaut-hub-control-plane
argocd                    21m         Normal    SuccessfulCreate                   replicaset/argocd-server-665b8b6947                              Created pod: argocd-server-665b8b6947-6lfjr
argocd                    21m         Normal    SuccessfulCreate                   statefulset/argocd-application-controller                        Create Pod argocd-application-controller-0 in StatefulSet argocd-application-controller successful
argocd                    21m         Normal    SuccessfulCreate                   replicaset/argocd-repo-server-57b98df6c6                         Created pod: argocd-repo-server-57b98df6c6-tbk5c
argocd                    21m         Normal    Scheduled                          pod/argocd-application-controller-0                              Successfully assigned argocd/argocd-application-controller-0 to kubernaut-hub-control-plane
argocd                    21m         Normal    Scheduled                          pod/argocd-redis-6bf744486c-2ld44                                Successfully assigned argocd/argocd-redis-6bf744486c-2ld44 to kubernaut-hub-control-plane
argocd                    21m         Normal    Pulling                            pod/argocd-applicationset-controller-7fb7c76f76-ssmwf            Pulling image "quay.io/argoproj/argocd:v3.5.3"
argocd                    21m         Normal    SuccessfulCreate                   replicaset/argocd-dex-server-7d54f7f9d6                          Created pod: argocd-dex-server-7d54f7f9d6-v77pf
argocd                    21m         Normal    ScalingReplicaSet                  deployment/argocd-repo-server                                    Scaled up replica set argocd-repo-server-57b98df6c6 from 0 to 1
argocd                    21m         Normal    Scheduled                          pod/argocd-server-665b8b6947-6lfjr                               Successfully assigned argocd/argocd-server-665b8b6947-6lfjr to kubernaut-hub-control-plane
argocd                    21m         Normal    Pulling                            pod/argocd-notifications-controller-7fcfd67447-58kqj             Pulling image "quay.io/argoproj/argocd:v3.5.3"
argocd                    21m         Normal    Pulling                            pod/argocd-application-controller-0                              Pulling image "quay.io/argoproj/argocd:v3.5.3"
argocd                    21m         Normal    Pulling                            pod/argocd-redis-6bf744486c-2ld44                                Pulling image "quay.io/argoproj/argocd:v3.5.3"
argocd                    21m         Normal    Pulling                            pod/argocd-repo-server-57b98df6c6-tbk5c                          Pulling image "quay.io/argoproj/argocd:v3.5.3"
argocd                    21m         Normal    Pulling                            pod/argocd-dex-server-7d54f7f9d6-v77pf                           Pulling image "quay.io/argoproj/argocd:v3.5.3"
argocd                    21m         Normal    Started                            pod/argocd-redis-6bf744486c-2ld44                                Container started
argocd                    21m         Normal    Started                            pod/argocd-dex-server-7d54f7f9d6-v77pf                           Container started
argocd                    21m         Normal    Pulled                             pod/argocd-dex-server-7d54f7f9d6-v77pf                           Successfully pulled image "quay.io/argoproj/argocd:v3.5.3" in 220ms (15.21s including waiting). Image size: 204754192 bytes.
argocd                    21m         Normal    Created                            pod/argocd-dex-server-7d54f7f9d6-v77pf                           Container created
argocd                    21m         Normal    Started                            pod/argocd-applicationset-controller-7fb7c76f76-ssmwf            Container started
argocd                    21m         Normal    Created                            pod/argocd-applicationset-controller-7fb7c76f76-ssmwf            Container created
argocd                    21m         Normal    Pulled                             pod/argocd-applicationset-controller-7fb7c76f76-ssmwf            Successfully pulled image "quay.io/argoproj/argocd:v3.5.3" in 15.08s (15.081s including waiting). Image size: 204754192 bytes.
argocd                    21m         Normal    Created                            pod/argocd-redis-6bf744486c-2ld44                                Container created
argocd                    21m         Normal    Pulled                             pod/argocd-server-665b8b6947-6lfjr                               Successfully pulled image "quay.io/argoproj/argocd:v3.5.3" in 253ms (15.437s including waiting). Image size: 204754192 bytes.
argocd                    21m         Warning   Failed                             pod/argocd-server-665b8b6947-6lfjr                               Error: secret "argocd-redis" not found
argocd                    21m         Normal    Pulled                             pod/argocd-redis-6bf744486c-2ld44                                Successfully pulled image "quay.io/argoproj/argocd:v3.5.3" in 308ms (15.47s including waiting). Image size: 204754192 bytes.
argocd                    21m         Normal    Pulled                             pod/argocd-notifications-controller-7fcfd67447-58kqj             Successfully pulled image "quay.io/argoproj/argocd:v3.5.3" in 383ms (15.956s including waiting). Image size: 204754192 bytes.
argocd                    21m         Normal    Pulling                            pod/argocd-redis-6bf744486c-2ld44                                Pulling image "public.ecr.aws/docker/library/redis:8.2.3-alpine"
argocd                    21m         Normal    Started                            pod/argocd-repo-server-57b98df6c6-tbk5c                          Container started
argocd                    21m         Normal    Pulling                            pod/argocd-server-665b8b6947-6lfjr                               Pulling image "quay.io/argoproj/argocd:v3.5.3"
argocd                    21m         Normal    Created                            pod/argocd-repo-server-57b98df6c6-tbk5c                          Container created
argocd                    21m         Normal    Pulled                             pod/argocd-repo-server-57b98df6c6-tbk5c                          Successfully pulled image "quay.io/argoproj/argocd:v3.5.3" in 254ms (15.595s including waiting). Image size: 204754192 bytes.
argocd                    21m         Normal    Created                            pod/argocd-notifications-controller-7fcfd67447-58kqj             Container created
argocd                    21m         Normal    Started                            pod/argocd-notifications-controller-7fcfd67447-58kqj             Container started
argocd                    21m         Normal    Created                            pod/argocd-application-controller-0                              Container created
argocd                    21m         Normal    Pulled                             pod/argocd-application-controller-0                              Successfully pulled image "quay.io/argoproj/argocd:v3.5.3" in 1.067s (17.006s including waiting). Image size: 204754192 bytes.
argocd                    21m         Normal    Pulling                            pod/argocd-repo-server-57b98df6c6-tbk5c                          Pulling image "quay.io/argoproj/argocd:v3.5.3"
argocd                    21m         Normal    Started                            pod/argocd-application-controller-0                              Container started
argocd                    21m         Normal    Started                            pod/argocd-redis-6bf744486c-2ld44                                Container started
argocd                    21m         Normal    Created                            pod/argocd-redis-6bf744486c-2ld44                                Container created
argocd                    21m         Normal    Pulled                             pod/argocd-redis-6bf744486c-2ld44                                Successfully pulled image "public.ecr.aws/docker/library/redis:8.2.3-alpine" in 6.521s (7.365s including waiting). Image size: 27546824 bytes.
argocd                    21m         Normal    Pulled                             pod/argocd-dex-server-7d54f7f9d6-v77pf                           Successfully pulled image "ghcr.io/dexidp/dex:v2.45.1" in 4.256s (11.583s including waiting). Image size: 43824487 bytes.
argocd                    21m         Normal    Started                            pod/argocd-repo-server-57b98df6c6-tbk5c                          Container started
argocd                    21m         Normal    Pulled                             pod/argocd-repo-server-57b98df6c6-tbk5c                          Successfully pulled image "quay.io/argoproj/argocd:v3.5.3" in 229ms (10.037s including waiting). Image size: 204754192 bytes.
argocd                    21m         Normal    Created                            pod/argocd-repo-server-57b98df6c6-tbk5c                          Container created
argocd                    21m         Normal    Started                            pod/argocd-server-665b8b6947-6lfjr                               Container started
argocd                    21m         Normal    Pulled                             pod/argocd-server-665b8b6947-6lfjr                               Successfully pulled image "quay.io/argoproj/argocd:v3.5.3" in 281ms (11.854s including waiting). Image size: 204754192 bytes.
argocd                    21m         Normal    Created                            pod/argocd-server-665b8b6947-6lfjr                               Container created
argocd                    21m         Normal    Pulled                             pod/argocd-dex-server-7d54f7f9d6-v77pf                           Successfully pulled image "ghcr.io/dexidp/dex:v2.45.1" in 368ms (368ms including waiting). Image size: 43824487 bytes.
argocd                    21m         Normal    Pulling                            pod/argocd-dex-server-7d54f7f9d6-v77pf                           Pulling image "ghcr.io/dexidp/dex:v2.45.1"
argocd                    21m         Normal    Created                            pod/argocd-dex-server-7d54f7f9d6-v77pf                           Container created
argocd                    21m         Normal    Started                            pod/argocd-dex-server-7d54f7f9d6-v77pf                           Container started
kubernaut-system          10m         Normal    Scheduled                          pod/kubernaut-crd-upgrade-b79wh                                  Successfully assigned kubernaut-system/kubernaut-crd-upgrade-b79wh to kubernaut-hub-control-plane
kubernaut-system          10m         Normal    SuccessfulCreate                   job/kubernaut-crd-upgrade                                        Created pod: kubernaut-crd-upgrade-b79wh
kubernaut-system          10m         Normal    Pulling                            pod/kubernaut-crd-upgrade-b79wh                                  Pulling image "docker.io/bitnami/kubectl:latest@sha256:6e2cdb22d6ab7264ea198c717f555e30536b54029d26c8781b9f25f78951b564"
kubernaut-system          10m         Normal    Pulled                             pod/kubernaut-crd-upgrade-b79wh                                  Successfully pulled image "docker.io/bitnami/kubectl:latest@sha256:6e2cdb22d6ab7264ea198c717f555e30536b54029d26c8781b9f25f78951b564" in 471ms (471ms including waiting). Image size: 71257358 bytes.
kubernaut-system          10m         Normal    Created                            pod/kubernaut-crd-upgrade-b79wh                                  Container created
kubernaut-system          10m         Normal    Started                            pod/kubernaut-crd-upgrade-b79wh                                  Container started
kubernaut-system          10m         Normal    Scheduled                          pod/kubernaut-tls-cert-gen-pwgfg                                 Successfully assigned kubernaut-system/kubernaut-tls-cert-gen-pwgfg to kubernaut-hub-control-plane
kubernaut-system          10m         Normal    SuccessfulCreate                   job/kubernaut-tls-cert-gen                                       Created pod: kubernaut-tls-cert-gen-pwgfg
kubernaut-system          10m         Normal    Completed                          job/kubernaut-crd-upgrade                                        Job completed
kubernaut-system          10m         Normal    Created                            pod/kubernaut-tls-cert-gen-pwgfg                                 Container created
kubernaut-system          10m         Normal    Pulling                            pod/kubernaut-tls-cert-gen-pwgfg                                 Pulling image "docker.io/bitnami/kubectl:latest@sha256:6e2cdb22d6ab7264ea198c717f555e30536b54029d26c8781b9f25f78951b564"
kubernaut-system          10m         Normal    Pulled                             pod/kubernaut-tls-cert-gen-pwgfg                                 Successfully pulled image "docker.io/bitnami/kubectl:latest@sha256:6e2cdb22d6ab7264ea198c717f555e30536b54029d26c8781b9f25f78951b564" in 305ms (305ms including waiting). Image size: 71257358 bytes.
kubernaut-system          10m         Normal    Started                            pod/kubernaut-tls-cert-gen-pwgfg                                 Container started
kubernaut-system          9m44s       Normal    Completed                          job/kubernaut-tls-cert-gen                                       Job completed
kubernaut-system          9m42s       Normal    Scheduled                          pod/gateway-588c9d65cc-dlzbm                                     Successfully assigned kubernaut-system/gateway-588c9d65cc-dlzbm to kubernaut-hub-control-plane
kubernaut-system          9m42s       Normal    NoPods                             poddisruptionbudget/gateway                                      No matching pods found
kubernaut-system          9m42s       Normal    SuccessfulCreate                   replicaset/gateway-588c9d65cc                                    Created pod: gateway-588c9d65cc-dlzbm
kubernaut-system          9m42s       Normal    ScalingReplicaSet                  deployment/gateway                                               Scaled up replica set gateway-588c9d65cc from 0 to 1
kubernaut-system          9m41s       Normal    Pulling                            pod/gateway-588c9d65cc-dlzbm                                     Pulling image "quay.io/kubernaut-ai/gateway:1.6.0-rc20"
kubernaut-system          9m36s       Normal    Pulled                             pod/gateway-588c9d65cc-dlzbm                                     Successfully pulled image "quay.io/kubernaut-ai/gateway:1.6.0-rc20" in 5.326s (5.326s including waiting). Image size: 19644034 bytes.
kubernaut-system          9m36s       Normal    Created                            pod/gateway-588c9d65cc-dlzbm                                     Container created
kubernaut-system          9m36s       Normal    Started                            pod/gateway-588c9d65cc-dlzbm                                     Container started
kubernaut-system          9m2s        Normal    SignalProcessed                    signalprocessing/sp-rr-7f1635052972-0a08bdf0                     Signal processed successfully in 0.51s: P0 Production alert ready for remediation
kubernaut-system          9m2s        Normal    PhaseTransition                    signalprocessing/sp-rr-7f1635052972-0a08bdf0                     Phase transition: Pending → Enriching
kubernaut-system          9m2s        Normal    SignalEnriched                     signalprocessing/sp-rr-7f1635052972-0a08bdf0                     K8s context enriched: Deployment demo-storefront/worker
kubernaut-system          9m2s        Normal    PhaseTransition                    signalprocessing/sp-rr-7f1635052972-0a08bdf0                     Phase transition: Enriching → Classifying
kubernaut-system          9m2s        Normal    PhaseTransition                    signalprocessing/sp-rr-7f1635052972-0a08bdf0                     Phase transition: Classifying → Categorizing
kubernaut-system          9m2s        Normal    SessionCreated                     aianalysis/ai-rr-7f1635052972-0a08bdf0                           AgentSession as-rr-7f1635052972-0a08bdf0 created
kubernaut-system          9m2s        Normal    PhaseTransition                    aianalysis/ai-rr-7f1635052972-0a08bdf0                           Phase transition: Pending → Investigating
kubernaut-system          9m2s        Normal    AIAnalysisCreated                  aianalysis/ai-rr-7f1635052972-0a08bdf0                           AIAnalysis processing started
kubernaut-system          9m2s        Normal    RemediationCreated                 remediationrequest/rr-7f1635052972-0a08bdf0                      RemediationRequest accepted for signal KubePodCrashLooping
kubernaut-system          9m2s        Normal    PhaseTransition                    signalprocessing/sp-rr-7f1635052972-0a08bdf0                     Phase transition: Categorizing → Completed
kubernaut-system          9m2s        Normal    PhaseTransition                    remediationrequest/rr-7f1635052972-0a08bdf0                      Phase transition: Processing → Analyzing
kubernaut-system          9m2s        Normal    PhaseTransition                    remediationrequest/rr-7f1635052972-0a08bdf0                      Phase transition: Pending → Processing
kubernaut-system          8m45s       Normal    Scheduled                          pod/kubernaut-crd-upgrade-s749n                                  Successfully assigned kubernaut-system/kubernaut-crd-upgrade-s749n to kubernaut-hub-control-plane
kubernaut-system          8m45s       Normal    SuccessfulCreate                   job/kubernaut-crd-upgrade                                        Created pod: kubernaut-crd-upgrade-s749n
kubernaut-system          8m44s       Normal    Pulling                            pod/kubernaut-crd-upgrade-s749n                                  Pulling image "docker.io/bitnami/kubectl:latest@sha256:6e2cdb22d6ab7264ea198c717f555e30536b54029d26c8781b9f25f78951b564"
kubernaut-system          8m43s       Normal    Created                            pod/kubernaut-crd-upgrade-s749n                                  Container created
kubernaut-system          8m43s       Normal    Pulled                             pod/kubernaut-crd-upgrade-s749n                                  Successfully pulled image "docker.io/bitnami/kubectl:latest@sha256:6e2cdb22d6ab7264ea198c717f555e30536b54029d26c8781b9f25f78951b564" in 509ms (509ms including waiting). Image size: 71257358 bytes.
kubernaut-system          8m43s       Normal    Started                            pod/kubernaut-crd-upgrade-s749n                                  Container started
kubernaut-system          8m29s       Normal    SuccessfulCreate                   job/kubernaut-tls-cert-gen                                       Created pod: kubernaut-tls-cert-gen-pqfjq
kubernaut-system          8m29s       Normal    Scheduled                          pod/kubernaut-tls-cert-gen-pqfjq                                 Successfully assigned kubernaut-system/kubernaut-tls-cert-gen-pqfjq to kubernaut-hub-control-plane
kubernaut-system          8m29s       Normal    Completed                          job/kubernaut-crd-upgrade                                        Job completed
kubernaut-system          8m28s       Normal    Pulled                             pod/kubernaut-tls-cert-gen-pqfjq                                 Successfully pulled image "docker.io/bitnami/kubectl:latest@sha256:6e2cdb22d6ab7264ea198c717f555e30536b54029d26c8781b9f25f78951b564" in 297ms (297ms including waiting). Image size: 71257358 bytes.
kubernaut-system          8m28s       Normal    Created                            pod/kubernaut-tls-cert-gen-pqfjq                                 Container created
kubernaut-system          8m28s       Normal    Pulling                            pod/kubernaut-tls-cert-gen-pqfjq                                 Pulling image "docker.io/bitnami/kubectl:latest@sha256:6e2cdb22d6ab7264ea198c717f555e30536b54029d26c8781b9f25f78951b564"
kubernaut-system          8m27s       Normal    Started                            pod/kubernaut-tls-cert-gen-pqfjq                                 Container started
kubernaut-system          8m13s       Normal    Completed                          job/kubernaut-tls-cert-gen                                       Job completed
kubernaut-system          8m10s       Normal    SuccessfulCreate                   replicaset/signalprocessing-controller-5c4c69cd6f                Created pod: signalprocessing-controller-5c4c69cd6f-8trbz
kubernaut-system          8m10s       Normal    Started                            pod/signalprocessing-controller-5c4c69cd6f-8trbz                 Container started
kubernaut-system          8m10s       Normal    Created                            pod/signalprocessing-controller-5c4c69cd6f-8trbz                 Container created
kubernaut-system          8m10s       Normal    Pulled                             pod/signalprocessing-controller-5c4c69cd6f-8trbz                 Container image "quay.io/kubernaut-ai/signalprocessing:1.6.0-rc20" already present on machine and can be accessed by the pod
kubernaut-system          8m10s       Normal    ScalingReplicaSet                  deployment/signalprocessing-controller                           Scaled up replica set signalprocessing-controller-5c4c69cd6f from 0 to 1
kubernaut-system          8m10s       Normal    Scheduled                          pod/signalprocessing-controller-5c4c69cd6f-8trbz                 Successfully assigned kubernaut-system/signalprocessing-controller-5c4c69cd6f-8trbz to kubernaut-hub-control-plane
kubernaut-system          8m4s        Normal    SuccessfulDelete                   replicaset/signalprocessing-controller-69648fdd9c                Deleted pod: signalprocessing-controller-69648fdd9c-rsqzp
kubernaut-system          8m4s        Normal    ScalingReplicaSet                  deployment/signalprocessing-controller                           Scaled down replica set signalprocessing-controller-69648fdd9c from 1 to 0
kubernaut-system          8m4s        Normal    Killing                            pod/signalprocessing-controller-69648fdd9c-rsqzp                 Stopping container signalprocessing-controller
kubernaut-system          8m1s        Normal    Pulled                             pod/kubernaut-db-migration-2gvzh                                 Container image "quay.io/kubernaut-ai/db-migrate:1.6.0-rc20" already present on machine and can be accessed by the pod
kubernaut-system          8m1s        Normal    Scheduled                          pod/kubernaut-db-migration-2gvzh                                 Successfully assigned kubernaut-system/kubernaut-db-migration-2gvzh to kubernaut-hub-control-plane
kubernaut-system          8m1s        Normal    Created                            pod/kubernaut-db-migration-2gvzh                                 Container created
kubernaut-system          8m1s        Normal    SuccessfulCreate                   job/kubernaut-db-migration                                       Created pod: kubernaut-db-migration-2gvzh
kubernaut-system          8m          Normal    Started                            pod/kubernaut-db-migration-2gvzh                                 Container started
kubernaut-system          7m55s       Normal    PhaseTransition                    aianalysis/ai-rr-7f1635052972-0a08bdf0                           Phase transition: Analyzing → Completed
kubernaut-system          7m55s       Normal    AnalysisCompleted                  aianalysis/ai-rr-7f1635052972-0a08bdf0                           Analysis completed successfully
kubernaut-system          7m55s       Normal    PhaseTransition                    aianalysis/ai-rr-7f1635052972-0a08bdf0                           Phase transition: Investigating → Analyzing
kubernaut-system          7m55s       Normal    InvestigationComplete              aianalysis/ai-rr-7f1635052972-0a08bdf0                           Investigation completed successfully, transitioning to Analyzing
kubernaut-system          7m54s       Normal    PhaseTransition                    remediationrequest/rr-7f1635052972-0a08bdf0                      Phase transition: Analyzing → Executing
kubernaut-system          7m54s       Normal    Created                            pod/kubernaut-db-migration-2gvzh                                 Container created
kubernaut-system          7m54s       Normal    Pulled                             pod/kubernaut-db-migration-2gvzh                                 Container image "quay.io/kubernaut-ai/db-migrate:1.6.0-rc20" already present on machine and can be accessed by the pod
kubernaut-system          7m54s       Normal    WorkflowValidated                  workflowexecution/we-rr-7f1635052972-0a08bdf0                    Workflow spec validated: 0aa9e14b-13ab-5b61-af2f-c78ccf4e8d24 (target: demo-storefront/ConfigMap/worker-config)
kubernaut-system          7m54s       Normal    ExecutionCreated                   workflowexecution/we-rr-7f1635052972-0a08bdf0                    Created job execution resource kubernaut-workflows/wfe-b5b9751881488bb8
kubernaut-system          7m54s       Normal    PhaseTransition                    workflowexecution/we-rr-7f1635052972-0a08bdf0                    Phase transition: Pending → Running
kubernaut-system          7m53s       Normal    Started                            pod/kubernaut-db-migration-2gvzh                                 Container started
kubernaut-system          7m49s       Normal    Completed                          job/kubernaut-db-migration                                       Job completed
kubernaut-system          7m48s       Normal    SuccessfulCreate                   job/kubernaut-tls-cabundle-patch                                 Created pod: kubernaut-tls-cabundle-patch-hb5t6
kubernaut-system          7m48s       Normal    Scheduled                          pod/kubernaut-tls-cabundle-patch-hb5t6                           Successfully assigned kubernaut-system/kubernaut-tls-cabundle-patch-hb5t6 to kubernaut-hub-control-plane
kubernaut-system          7m48s       Normal    Pulling                            pod/kubernaut-tls-cabundle-patch-hb5t6                           Pulling image "docker.io/bitnami/kubectl:latest@sha256:6e2cdb22d6ab7264ea198c717f555e30536b54029d26c8781b9f25f78951b564"
kubernaut-system          7m47s       Normal    Pulled                             pod/kubernaut-tls-cabundle-patch-hb5t6                           Successfully pulled image "docker.io/bitnami/kubectl:latest@sha256:6e2cdb22d6ab7264ea198c717f555e30536b54029d26c8781b9f25f78951b564" in 432ms (432ms including waiting). Image size: 71257358 bytes.
kubernaut-system          7m47s       Normal    Created                            pod/kubernaut-tls-cabundle-patch-hb5t6                           Container created
kubernaut-system          7m47s       Normal    Started                            pod/kubernaut-tls-cabundle-patch-hb5t6                           Container started
kubernaut-system          7m39s       Normal    Completed                          job/kubernaut-tls-cabundle-patch                                 Job completed
kubernaut-system          7m33s       Normal    AssessmentScheduled                effectivenessassessment/ea-rr-7f1635052972-0a08bdf0              Assessment scheduled for correlation rr-7f1635052972-0a08bdf0 (deadline: 20:03:48)
kubernaut-system          7m33s       Normal    PhaseTransition                    workflowexecution/we-rr-7f1635052972-0a08bdf0                    Phase transition: Running → Completed
kubernaut-system          7m33s       Normal    WorkflowCompleted                  workflowexecution/we-rr-7f1635052972-0a08bdf0                    Workflow 0aa9e14b-13ab-5b61-af2f-c78ccf4e8d24 completed successfully in &Duration{Duration:22s,}
kubernaut-system          7m33s       Normal    EffectivenessAssessmentCreated     remediationrequest/rr-7f1635052972-0a08bdf0                      Created EffectivenessAssessment ea-rr-7f1635052972-0a08bdf0 (correlationID: rr-7f1635052972-0a08bdf0)
kubernaut-system          7m33s       Normal    RemediationCompleted               remediationrequest/rr-7f1635052972-0a08bdf0                      Remediation succeeded, entering verification phase (#280)
kubernaut-system          6m32s       Normal    LockReleased                       workflowexecution/we-rr-7f1635052972-0a08bdf0                    Lock released for demo-storefront/ConfigMap/worker-config after cooldown
default                   2m53s       Warning   FailedNodeAllocatableEnforcement   node/kubernaut-hub-control-plane                                 Failed to update Node Allocatable Limits ["kubelet" "kubepods"]: openat2 /sys/fs/cgroup/kubelet.slice/kubelet-kubepods.slice/cpuset.cpus: no such file or directory
kubernaut-system          2m33s       Warning   ValidityWindowExtended             effectivenessassessment/ea-rr-7f1635052972-0a08bdf0              StabilizationWindow (5m0s) >= ValidityWindow (2m0s); extended deadline to 2026-10-01 20:03:48 +0000 UTC
kubernaut-system          2m33s       Normal    ReconcileStarted                   notificationrequest/nr-completion-rr-7f1635052972-0a08bdf0       Started reconciling notification nr-completion-rr-7f1635052972-0a08bdf0
kubernaut-system          2m33s       Normal    PhaseTransition                    notificationrequest/nr-completion-rr-7f1635052972-0a08bdf0       Transitioned to Sending phase
kubernaut-system          2m33s       Normal    NotificationSent                   notificationrequest/nr-completion-rr-7f1635052972-0a08bdf0       Successfully delivered to channel console
kubernaut-system          2m33s       Normal    ComponentAssessed                  effectivenessassessment/ea-rr-7f1635052972-0a08bdf0              Component hash computed (match: 0x497cf066c643)
kubernaut-system          2m33s       Normal    ComponentAssessed                  effectivenessassessment/ea-rr-7f1635052972-0a08bdf0              Component alert assessed (score: 0.00)
kubernaut-system          2m33s       Normal    ComponentAssessed                  effectivenessassessment/ea-rr-7f1635052972-0a08bdf0              Component metrics assessed (score: 0.00)
kubernaut-system          2m33s       Normal    NotificationCreated                remediationrequest/rr-7f1635052972-0a08bdf0                      Completion notification created: nr-completion-rr-7f1635052972-0a08bdf0
kubernaut-system          2m33s       Normal    AssessmentStarted                  effectivenessassessment/ea-rr-7f1635052972-0a08bdf0              Assessment started for correlation rr-7f1635052972-0a08bdf0
kubernaut-system          2m33s       Normal    EffectivenessAssessed              effectivenessassessment/ea-rr-7f1635052972-0a08bdf0              Assessment completed: Full (correlation: rr-7f1635052972-0a08bdf0)
